Workbook

Sheet Cover
A1: VESTAS WIND SYSTEMS A/S
A2: Discounted Cash Flow Valuation & Investment Case
A3: Prepared by Nicolo Di Lena | Valuation date: 21 August 2026 | EUR million unless stated
A5: COMPANY SNAPSHOT
A6: Ticker / exchange | B6: VWS / Nasdaq Copenhagen
A7: Bloomberg | B7: VWS DC Equity
A8: Sector | B8: Wind turbine OEM and long-term service
A9: Reporting currency / listing currency | B9: EUR / DKK
A10: Fiscal year end | B10: 31 December
A11: FY2025 revenue / combined order backlog | B11: EUR 18.8bn / EUR 71.9bn
A13: VALUATION SUMMARY (live - updates with the model)
A14: Enterprise value (EUR m) | B14: =DCF!H31
A15: Equity value (EUR m) | B15: =DCF!H34
A16: Implied value per share, DKK - Gordon growth | B16: =DCF!H37
A17: Implied value per share, DKK - exit EV/EBITDA | B17: =DCF!H50
A18: Current share price (DKK) | B18: =DCF!$B$12
A19: Upside / (downside) - Gordon growth | B19: =DCF!H39
A20: RECOMMENDATION | B20: ='Football Field'!B15
A21: WACC | B21: =DCF!$B$5
A22: Terminal growth rate | B22: =DCF!$B$6
A23: Terminal value as % of enterprise value | B23: =DCF!H32
A24: Reverse DCF: perpetuity growth the market is pricing | B24: =DCF!H64 | D24: If this is far above your g, the market disagrees with you - explain why.
A26: HOW THIS WORKBOOK IS BUILT (read the tabs in this order)
A27: Football Field | B27: One-page valuation range and the recommendation rule.
A28: DCF | B28: Discounting, two terminal value methods, EV-to-equity bridge, reverse DCF.
A29: Sensitivity | B29: Four grids. WACC x g, upside/downside, WACC x exit multiple, execution risk.
A30: Scenarios | B30: Three live parallel models: bear, base, bull.
A31: Comps | B31: Trading comparables and the implied multiple valuation.
A32: P&L | B32: Forecast income statement. Pure formulas.
A33: FCF | B33: Unlevered free cash flow bridge plus cash quality checks.
A34: Assumptions | B34: Every driver you control, plus the scenario engine.
A35: WACC | B35: Full CAPM build-up with dated, sourced inputs.
A36: Historical | B36: Four to five years of reported actuals with sources.
A37: Checks | B37: Twelve integrity tests. Open this before you show anyone anything.
A39: FORMATTING CONVENTION (this is how banks read a model)
A40: Hardcoded input | B40: Blue font, orange fill. You may change these.
A41: Formula on this sheet | B41: Black font. Never type over it.
A42: Link to another sheet | B42: Green font. Never type over it.
A43: Output / result | B43: Light blue fill.
A45: Version note | B45: v2.0 - rebuilt 21-Aug-2026. v1 is preserved in the _archive folder. See the review document for every change and why.

Sheet Football Field
A1: VALUATION SUMMARY — FOOTBALL FIELD
A2: Ranges in DKK per share. This chart is the first page of any real investment memo.
A4: Methodology | B4: Low | C4: Span (low->high) | D4: High | E4: Midpoint
A5: DCF - Gordon growth (WACC +/-75bp, g +/-75bp) | B5: =MIN(Sensitivity!C8:I14) | C5: =D5-B5 | D5: =MAX(Sensitivity!C8:I14) | E5: =(B5+D5)/2
A6: DCF - exit EV/EBITDA (8.5x-11.5x) | B6: =MIN(Sensitivity!C28:I34) | C6: =D6-B6 | D6: =MAX(Sensitivity!C28:I34) | E6: =(B6+D6)/2
A7: Trading comps - EV/EBITDA (8.5x-11.5x) | B7: =Comps!B20 | C7: =D7-B7 | D7: =Comps!D20 | E7: =(B7+D7)/2
A8: Trading comps - EV/Revenue (0.95x-1.45x) | B8: =Comps!B30 | C8: =D8-B8 | D8: =Comps!D30 | E8: =(B8+D8)/2
A9: 52-week trading range | B9: 112 | C9: =D9-B9 | D9: 213.5 | E9: =(B9+D9)/2
A10: Broker consensus target (25 analysts) | B10: 212 | C10: =D10-B10 | D10: 212 | E10: =(B10+D10)/2
A12: CURRENT SHARE PRICE (DKK) | B12: =DCF!$B$12
A13: Base case DCF (Gordon growth) | B13: =DCF!H37
A14: Base case DCF (exit multiple) | B14: =DCF!H50
A15: Recommendation | B15: =IF(DCF!H39>0.15,"BUY",IF(DCF!H39<-0.15,"SELL","HOLD")) | G15: Mechanical rule: >+15% BUY, <-15% SELL, otherwise HOLD. State your rule in the memo.

Sheet DCF
A1: DISCOUNTED CASH FLOW — VALUATION
A2: Two terminal value methods, a full EV-to-equity bridge, an implied share price and a reverse DCF.
A4: KEY PARAMETERS
A5: WACC (discount rate) | B5: =Assumptions!B38
A6: Terminal growth rate (g) | B6: =Assumptions!B39
A7: Exit EV/EBITDA multiple | B7: =Assumptions!B40
A8: Mid-year convention (1 = yes) | B8: =Assumptions!B41
A9: Net cash / (net debt), EUR m | B9: =Historical!F31 | I9: POSITIVE = net cash, so it is ADDED to enterprise value.
A10: Diluted shares outstanding (m) | B10: =Historical!F32
A11: EUR / DKK | B11: =WACC!B22
A12: Current share price (DKK) | B12: =WACC!B20
A14: STEP 1 — DISCOUNT THE EXPLICIT FORECAST
A15: EUR m | B15: 2026E | C15: 2027E | D15: 2028E | E15: 2029E | F15: 2030E | H15: Total
A16: Unlevered free cash flow | B16: =FCF!C13 | C16: =FCF!D13 | D16: =FCF!E13 | E16: =FCF!F13 | F16: =FCF!G13
A17: Discount period (years) | B17: =IF($B$8=1,COLUMN()-COLUMN($B$17)+0.5,COLUMN()-COLUMN($B$17)+1) | C17: =IF($B$8=1,COLUMN()-COLUMN($B$17)+0.5,COLUMN()-COLUMN($B$17)+1) | D17: =IF($B$8=1,COLUMN()-COLUMN($B$17)+0.5,COLUMN()-COLUMN($B$17)+1) | E17: =IF($B$8=1,COLUMN()-COLUMN($B$17)+0.5,COLUMN()-COLUMN($B$17)+1) | F17: =IF($B$8=1,COLUMN()-COLUMN($B$17)+0.5,COLUMN()-COLUMN($B$17)+1) | I17: Mid-year: 0.5, 1.5, 2.5... Year-end: 1, 2, 3...
A18: Discount factor | B18: =1/(1+$B$5)^B17 | C18: =1/(1+$B$5)^C17 | D18: =1/(1+$B$5)^D17 | E18: =1/(1+$B$5)^E17 | F18: =1/(1+$B$5)^F17
A19: Present value of FCF | B19: =B16*B18 | C19: =C16*C18 | D19: =D16*D18 | E19: =E16*E18 | F19: =F16*F18 | H19: =SUM(B19:F19)
A21: STEP 2 — TERMINAL VALUE, METHOD 1: PERPETUITY (GORDON) GROWTH
A22: Terminal year FCF = 2030E FCF x (1 + g) | F22: =F16*(1+$B$6)
A23: Terminal value at end of 2030E = TFCF / (WACC - g) | F23: =F22/($B$5-$B$6)
A24: Discount factor at end of year 5 | F24: =1/(1+$B$5)^5 | I24: TV sits at 31-Dec-2030, so it is discounted a full 5 years even under mid-year.
A25: Present value of terminal value | F25: =F23*F24 | H25: =F25
A26: Exit EV/EBITDA implied by the Gordon terminal value | F26: =F23/'P&L'!G13 | I26: Sanity check: is that multiple plausible versus where the sector trades today?
A28: STEP 3 — VALUATION BRIDGE (GORDON GROWTH)
A29: Present value of explicit forecast FCF (2026E-2030E) | H29: =H19
A30: Present value of terminal value | H30: =H25
A31: ENTERPRISE VALUE | H31: =H29+H30
A32: Terminal value as % of enterprise value | H32: =H30/H31 | I32: Above roughly 75% and the reviewer stops believing the explicit forecast matters.
A33: (+) Net cash / (-) net debt | H33: =$B$9
A34: EQUITY VALUE | H34: =H31+H33
A35: Diluted shares outstanding (m) | H35: =$B$10
A36: IMPLIED VALUE PER SHARE (EUR) | H36: =H34/H35
A37: IMPLIED VALUE PER SHARE (DKK) | H37: =H36*$B$11
A38: Current share price (DKK) | H38: =$B$12
A39: UPSIDE / (DOWNSIDE) | H39: =H37/H38-1
A41: STEP 4 — TERMINAL VALUE, METHOD 2: EXIT EV/EBITDA MULTIPLE (CROSS-CHECK)
A42: 2030E EBITDA | F42: ='P&L'!G13
A43: Exit EV/EBITDA multiple | F43: =$B$7
A44: Terminal value at end of 2030E | F44: =F42*F43
A45: Present value of terminal value | F45: =F44*F24
...

Sheet Sensitivity
A1: SENSITIVITY ANALYSIS
A2: Every cell rebuilds the whole DCF from the free cash flow stream. No Excel Data Table, no volatile functions, nothing to refresh manually.
B4: Base case implied price (DKK) | C4: =DCF!H37 | E4: Current market price (DKK) | F4: =DCF!$B$12
A6: TABLE 1 — IMPLIED SHARE PRICE (DKK): WACC (across) x TERMINAL GROWTH g (down)
B7: g \ WACC | C7: =DCF!$B$5-0.0075 | D7: =DCF!$B$5-0.0050 | E7: =DCF!$B$5-0.0025 | F7: =DCF!$B$5+0.0000 | G7: =DCF!$B$5+0.0025 | H7: =DCF!$B$5+0.0050 | I7: =DCF!$B$5+0.0075
B8: =DCF!$B$6-0.0075 | C8: =(DCF!$B$16/(1+C$7)^DCF!$B$17+DCF!$C$16/(1+C$7)^DCF!$C$17+DCF!$D$16/(1+C$7)^DCF!$D$17+DCF!$E$16/(1+C$7)^DCF!$E$17+DCF!$F$16/(1+C$7)^DCF!$F$17+DCF!$F$16*(1+$B8)/(C$7-$B8)/(1+C$7)^5+DCF!$B$9)/DCF!$B$10*DCF!$B$11 | D8: =(DCF!$B$16/(1+D$7)^DCF!$B$17+DCF!$C$16/(1+D$7)^DCF!$C$17+DCF!$D$16/(1+D$7)^DCF!$D$17+DCF!$E$16/(1+D$7)^DCF!$E$17+DCF!$F$16/(1+D$7)^DCF!$F$17+DCF!$F$16*(1+$B8)/(D$7-$B8)/(1+D$7)^5+DCF!$B$9)/DCF!$B$10*DCF!$B$11 | E8: =(DCF!$B$16/(1+E$7)^DCF!$B$17+DCF!$C$16/(1+E$7)^DCF!$C$17+DCF!$D$16/(1+E$7)^DCF!$D$17+DCF!$E$16/(1+E$7)^DCF!$E$17+DCF!$F$16/(1+E$7)^DCF!$F$17+DCF!$F$16*(1+$B8)/(E$7-$B8)/(1+E$7)^5+DCF!$B$9)/DCF!$B$10*DCF!$B$11 | F8: =(DCF!$B$16/(1+F$7)^DCF!$B$17+DCF!$C$16/(1+F$7)^DCF!$C$17+DCF!$D$16/(1+F$7)^DCF!$D$17+DCF!$E$16/(1+F$7)^DCF!$E$17+DCF!$F$16/(1+F$7)^DCF!$F$17+DCF!$F$16*(1+$B8)/(F$7-$B8)/(1+F$7)^5+DCF!$B$9)/DCF!$B$10*DCF!$B$11 | G8: =(DCF!$B$16/(1+G$7)^DCF!$B$17+DCF!$C$16/(1+G$7)^DCF!$C$17+DCF!$D$16/(1+G$7)^DCF!$D$17+DCF!$E$16/(1+G$7)^DCF!$E$17+DCF!$F$16/(1+G$7)^DCF!$F$17+DCF!$F$16*(1+$B8)/(G$7-$B8)/(1+G$7)^5+DCF!$B$9)/DCF!$B$10*DCF!$B$11 | H8: =(DCF!$B$16/(1+H$7)^DCF!$B$17+DCF!$C$16/(1+H$7)^DCF!$C$17+DCF!$D$16/(1+H$7)^DCF!$D$17+DCF!$E$16/(1+H$7)^DCF!$E$17+DCF!$F$16/(1+H$7)^DCF!$F$17+DCF!$F$16*(1+$B8)/(H$7-$B8)/(1+H$7)^5+DCF!$B$9)/DCF!$B$10*DCF!$B$11 | I8: =(DCF!$B$16/(1+I$7)^DCF!$B$17+DCF!$C$16/(1+I$7)^DCF!$C$17+DCF!$D$16/(1+I$7)^DCF!$D$17+DCF!$E$16/(1+I$7)^DCF!$E$17+DCF!$F$16/(1+I$7)^DCF!$F$17+DCF!$F$16*(1+$B8)/(I$7-$B8)/(1+I$7)^5+DCF!$B$9)/DCF!$B$10*DCF!$B$11
B9: =DCF!$B$6-0.0050 | C9: =(DCF!$B$16/(1+C$7)^DCF!$B$17+DCF!$C$16/(1+C$7)^DCF!$C$17+DCF!$D$16/(1+C$7)^DCF!$D$17+DCF!$E$16/(1+C$7)^DCF!$E$17+DCF!$F$16/(1+C$7)^DCF!$F$17+DCF!$F$16*(1+$B9)/(C$7-$B9)/(1+C$7)^5+DCF!$B$9)/DCF!$B$10*DCF!$B$11 | D9: =(DCF!$B$16/(1+D$7)^DCF!$B$17+DCF!$C$16/(1+D$7)^DCF!$C$17+DCF!$D$16/(1+D$7)^DCF!$D$17+DCF!$E$16/(1+D$7)^DCF!$E$17+DCF!$F$16/(1+D$7)^DCF!$F$17+DCF!$F$16*(1+$B9)/(D$7-$B9)/(1+D$7)^5+DCF!$B$9)/DCF!$B$10*DCF!$B$11 | E9: =(DCF!$B$16/(1+E$7)^DCF!$B$17+DCF!$C$16/(1+E$7)^DCF!$C$17+DCF!$D$16/(1+E$7)^DCF!$D$17+DCF!$E$16/(1+E$7)^DCF!$E$17+DCF!$F$16/(1+E$7)^DCF!$F$17+DCF!$F$16*(1+$B9)/(E$7-$B9)/(1+E$7)^5+DCF!$B$9)/DCF!$B$10*DCF!$B$11 | F9: =(DCF!$B$16/(1+F$7)^DCF!$B$17+DCF!$C$16/(1+F$7)^DCF!$C$17+DCF!$D$16/(1+F$7)^DCF!$D$17+DCF!$E$16/(1+F$7)^DCF!$E$17+DCF!$F$16/(1+F$7)^DCF!$F$17+DCF!$F$16*(1+$B9)/(F$7-$B9)/(1+F$7)^5+DCF!$B$9)/DCF!$B$10*DCF!$B$11 | G9: =(DCF!$B$16/(1+G$7)^DCF!$B$17+DCF!$C$16/(1+G$7)^DCF!$C$17+DCF!$D$16/(1+G$7)^DCF!$D$17+DCF!$E$16/(1+G$7)^DCF!$E$17+DCF!$F$16/(1+G$7)^DCF!$F$17+DCF!$F$16*(1+$B9)/(G$7-$B9)/(1+G$7)^5+DCF!$B$9)/DCF!$B$10*DCF!$B$11 | H9: =(DCF!$B$16/(1+H$7)^DCF!$B$17+DCF!$C$16/(1+H$7)^DCF!$C$17+DCF!$D$16/(1+H$7)^DCF!$D$17+DCF!$E$16/(1+H$7)^DCF!$E$17+DCF!$F$16/(1+H$7)^DCF!$F$17+DCF!$F$16*(1+$B9)/(H$7-$B9)/(1+H$7)^5+DCF!$B$9)/DCF!$B$10*DCF!$B$11 | I9: =(DCF!$B$16/(1+I$7)^DCF!$B$17+DCF!$C$16/(1+I$7)^DCF!$C$17+DCF!$D$16/(1+I$7)^DCF!$D$17+DCF!$E$16/(1+I$7)^DCF!$E$17+DCF!$F$16/(1+I$7)^DCF!$F$17+DCF!$F$16*(1+$B9)/(I$7-$B9)/(1+I$7)^5+DCF!$B$9)/DCF!$B$10*DCF!$B$11
B10: =DCF!$B$6-0.0025 | C10: =(DCF!$B$16/(1+C$7)^DCF!$B$17+DCF!$C$16/(1+C$7)^DCF!$C$17+DCF!$D$16/(1+C$7)^DCF!$D$17+DCF!$E$16/(1+C$7)^DCF!$E$17+DCF!$F$16/(1+C$7)^DCF!$F$17+DCF!$F$16*(1+$B10)/(C$7-$B10)/(1+C$7)^5+DCF!$B$9)/DCF!$B$10*DCF!$B$11 | D10: =(DCF!$B$16/(1+D$7)^DCF!$B$17+DCF!$C$16/(1+D$7)^DCF!$C$17+DCF!$D$16/(1+D$7)^DCF!$D$17+DCF!$E$16/(1+D$7)^DCF!$E$17+DCF!$F$16/(1+D$7)^DCF!$F$17+DCF!$F$16*(1+$B10)/(D$7-$B10)/(1+D$7)^5+DCF!$B$9)/DCF!$B$10*DCF!$B$11 | E10: =(DCF!$B$16/(1+E$7)^DCF!$B$17+DCF!$C$16/(1+E$7)^DCF!$C$17+DCF!$D$16/(1+E$7)^DCF!$D$17+DCF!$E$16/(1+E$7)^DCF!$E$17+DCF!$F$16/(1+E$7)^DCF!$F$17+DCF!$F$16*(1+$B10)/(E$7-$B10)/(1+E$7)^5+DCF!$B$9)/DCF!$B$10*DCF!$B$11 | F10: =(DCF!$B$16/(1+F$7)^DCF!$B$17+DCF!$C$16/(1+F$7)^DCF!$C$17+DCF!$D$16/(1+F$7)^DCF!$D$17+DCF!$E$16/(1+F$7)^DCF!$E$17+DCF!$F$16/(1+F$7)^DCF!$F$17+DCF!$F$16*(1+$B10)/(F$7-$B10)/(1+F$7)^5+DCF!$B$9)/DCF!$B$10*DCF!$B$11 | G10: =(DCF!$B$16/(1+G$7)^DCF!$B$17+DCF!$C$16/(1+G$7)^DCF!$C$17+DCF!$D$16/(1+G$7)^DCF!$D$17+DCF!$E$16/(1+G$7)^DCF!$E$17+DCF!$F$16/(1+G$7)^DCF!$F$17+DCF!$F$16*(1+$B10)/(G$7-$B10)/(1+G$7)^5+DCF!$B$9)/DCF!$B$10*DCF!$B$11 | H10: =(DCF!$B$16/(1+H$7)^DCF!$B$17+DCF!$C$16/(1+H$7)^DCF!$C$17+DCF!$D$16/(1+H$7)^DCF!$D$17+DCF!$E$16/(1+H$7)^DCF!$E$17+DCF!$F$16/(1+H$7)^DCF!$F$17+DCF!$F$16*(1+$B10)/(H$7-$B10)/(1+H$7)^5+DCF!$B$9)/DCF!$B$10*DCF!$B$11 | I10: =(DCF!$B$16/(1+I$7)^DCF!$B$17+DCF!$C$16/(1+I$7)^DCF!$C$17+DCF!$D$16/(1+I$7)^DCF!$D$17+DCF!$E$16/(1+I$7)^DCF!$E$17+DCF!$F$16/(1+I$7)^DCF!$F$17+DCF!$F$16*(1+$B10)/(I$7-$B10)/(1+I$7)^5+DCF!$B$9)/DCF!$B$10*DCF!$B$11
B11: =DCF!$B$6+0.0000 | C11: =(DCF!$B$16/(1+C$7)^DCF!$B$17+DCF!$C$16/(1+C$7)^DCF!$C$17+DCF!$D$16/(1+C$7)^DCF!$D$17+DCF!$E$16/(1+C$7)^DCF!$E$17+DCF!$F$16/(1+C$7)^DCF!$F$17+DCF!$F$16*(1+$B11)/(C$7-$B11)/(1+C$7)^5+DCF!$B$9)/DCF!$B$10*DCF!$B$11 | D11: =(DCF!$B$16/(1+D$7)^DCF!$B$17+DCF!$C$16/(1+D$7)^DCF!$C$17+DCF!$D$16/(1+D$7)^DCF!$D$17+DCF!$E$16/(1+D$7)^DCF!$E$17+DCF!$F$16/(1+D$7)^DCF!$F$17+DCF!$F$16*(1+$B11)/(D$7-$B11)/(1+D$7)^5+DCF!$B$9)/DCF!$B$10*DCF!$B$11 | E11: =(DCF!$B$16/(1+E$7)^DCF!$B$17+DCF!$C$16/(1+E$7)^DCF!$C$17+DCF!$D$16/(1+E$7)^DCF!$D$17+DCF!$E$16/(1+E$7)^DCF!$E$17+DCF!$F$16/(1+E$7)^DCF!$F$17+DCF!$F$16*(1+$B11)/(E$7-$B11)/(1+E$7)^5+DCF!$B$9)/DCF!$B$10*DCF!$B$11 | F11: =(DCF!$B$16/(1+F$7)^DCF!$B$17+DCF!$C$16/(1+F$7)^DCF!$C$17+DCF!$D$16/(1+F$7)^DCF!$D$17+DCF!$E$16/(1+F$7)^DCF!$E$17+DCF!$F$16/(1+F$7)^DCF!$F$17+DCF!$F$16*(1+$B11)/(F$7-$B11)/(1+F$7)^5+DCF!$B$9)/DCF!$B$10*DCF!$B$11 | G11: =(DCF!$B$16/(1+G$7)^DCF!$B$17+DCF!$C$16/(1+G$7)^DCF!$C$17+DCF!$D$16/(1+G$7)^DCF!$D$17+DCF!$E$16/(1+G$7)^DCF!$E$17+DCF!$F$16/(1+G$7)^DCF!$F$17+DCF!$F$16*(1+$B11)/(G$7-$B11)/(1+G$7)^5+DCF!$B$9)/DCF!$B$10*DCF!$B$11 | H11: =(DCF!$B$16/(1+H$7)^DCF!$B$17+DCF!$C$16/(1+H$7)^DCF!$C$17+DCF!$D$16/(1+H$7)^DCF!$D$17+DCF!$E$16/(1+H$7)^DCF!$E$17+DCF!$F$16/(1+H$7)^DCF!$F$17+DCF!$F$16*(1+$B11)/(H$7-$B11)/(1+H$7)^5+DCF!$B$9)/DCF!$B$10*DCF!$B$11 | I11: =(DCF!$B$16/(1+I$7)^DCF!$B$17+DCF!$C$16/(1+I$7)^DCF!$C$17+DCF!$D$16/(1+I$7)^DCF!$D$17+DCF!$E$16/(1+I$7)^DCF!$E$17+DCF!$F$16/(1+I$7)^DCF!$F$17+DCF!$F$16*(1+$B11)/(I$7-$B11)/(1+I$7)^5+DCF!$B$9)/DCF!$B$10*DCF!$B$11
B12: =DCF!$B$6+0.0025 | C12: =(DCF!$B$16/(1+C$7)^DCF!$B$17+DCF!$C$16/(1+C$7)^DCF!$C$17+DCF!$D$16/(1+C$7)^DCF!$D$17+DCF!$E$16/(1+C$7)^DCF!$E$17+DCF!$F$16/(1+C$7)^DCF!$F$17+DCF!$F$16*(1+$B12)/(C$7-$B12)/(1+C$7)^5+DCF!$B$9)/DCF!$B$10*DCF!$B$11 | D12: =(DCF!$B$16/(1+D$7)^DCF!$B$17+DCF!$C$16/(1+D$7)^DCF!$C$17+DCF!$D$16/(1+D$7)^DCF!$D$17+DCF!$E$16/(1+D$7)^DCF!$E$17+DCF!$F$16/(1+D$7)^DCF!$F$17+DCF!$F$16*(1+$B12)/(D$7-$B12)/(1+D$7)^5+DCF!$B$9)/DCF!$B$10*DCF!$B$11 | E12: =(DCF!$B$16/(1+E$7)^DCF!$B$17+DCF!$C$16/(1+E$7)^DCF!$C$17+DCF!$D$16/(1+E$7)^DCF!$D$17+DCF!$E$16/(1+E$7)^DCF!$E$17+DCF!$F$16/(1+E$7)^DCF!$F$17+DCF!$F$16*(1+$B12)/(E$7-$B12)/(1+E$7)^5+DCF!$B$9)/DCF!$B$10*DCF!$B$11 | F12: =(DCF!$B$16/(1+F$7)^DCF!$B$17+DCF!$C$16/(1+F$7)^DCF!$C$17+DCF!$D$16/(1+F$7)^DCF!$D$17+DCF!$E$16/(1+F$7)^DCF!$E$17+DCF!$F$16/(1+F$7)^DCF!$F$17+DCF!$F$16*(1+$B12)/(F$7-$B12)/(1+F$7)^5+DCF!$B$9)/DCF!$B$10*DCF!$B$11 | G12: =(DCF!$B$16/(1+G$7)^DCF!$B$17+DCF!$C$16/(1+G$7)^DCF!$C$17+DCF!$D$16/(1+G$7)^DCF!$D$17+DCF!$E$16/(1+G$7)^DCF!$E$17+DCF!$F$16/(1+G$7)^DCF!$F$17+DCF!$F$16*(1+$B12)/(G$7-$B12)/(1+G$7)^5+DCF!$B$9)/DCF!$B$10*DCF!$B$11 | H12: =(DCF!$B$16/(1+H$7)^DCF!$B$17+DCF!$C$16/(1+H$7)^DCF!$C$17+DCF!$D$16/(1+H$7)^DCF!$D$17+DCF!$E$16/(1+H$7)^DCF!$E$17+DCF!$F$16/(1+H$7)^DCF!$F$17+DCF!$F$16*(1+$B12)/(H$7-$B12)/(1+H$7)^5+DCF!$B$9)/DCF!$B$10*DCF!$B$11 | I12: =(DCF!$B$16/(1+I$7)^DCF!$B$17+DCF!$C$16/(1+I$7)^DCF!$C$17+DCF!$D$16/(1+I$7)^DCF!$D$17+DCF!$E$16/(1+I$7)^DCF!$E$17+DCF!$F$16/(1+I$7)^DCF!$F$17+DCF!$F$16*(1+$B12)/(I$7-$B12)/(1+I$7)^5+DCF!$B$9)/DCF!$B$10*DCF!$B$11
B13: =DCF!$B$6+0.0050 | C13: =(DCF!$B$16/(1+C$7)^DCF!$B$17+DCF!$C$16/(1+C$7)^DCF!$C$17+DCF!$D$16/(1+C$7)^DCF!$D$17+DCF!$E$16/(1+C$7)^DCF!$E$17+DCF!$F$16/(1+C$7)^DCF!$F$17+DCF!$F$16*(1+$B13)/(C$7-$B13)/(1+C$7)^5+DCF!$B$9)/DCF!$B$10*DCF!$B$11 | D13: =(DCF!$B$16/(1+D$7)^DCF!$B$17+DCF!$C$16/(1+D$7)^DCF!$C$17+DCF!$D$16/(1+D$7)^DCF!$D$17+DCF!$E$16/(1+D$7)^DCF!$E$17+DCF!$F$16/(1+D$7)^DCF!$F$17+DCF!$F$16*(1+$B13)/(D$7-$B13)/(1+D$7)^5+DCF!$B$9)/DCF!$B$10*DCF!$B$11 | E13: =(DCF!$B$16/(1+E$7)^DCF!$B$17+DCF!$C$16/(1+E$7)^DCF!$C$17+DCF!$D$16/(1+E$7)^DCF!$D$17+DCF!$E$16/(1+E$7)^DCF!$E$17+DCF!$F$16/(1+E$7)^DCF!$F$17+DCF!$F$16*(1+$B13)/(E$7-$B13)/(1+E$7)^5+DCF!$B$9)/DCF!$B$10*DCF!$B$11 | F13: =(DCF!$B$16/(1+F$7)^DCF!$B$17+DCF!$C$16/(1+F$7)^DCF!$C$17+DCF!$D$16/(1+F$7)^DCF!$D$17+DCF!$E$16/(1+F$7)^DCF!$E$17+DCF!$F$16/(1+F$7)^DCF!$F$17+DCF!$F$16*(1+$B13)/(F$7-$B13)/(1+F$7)^5+DCF!$B$9)/DCF!$B$10*DCF!$B$11 | G13: =(DCF!$B$16/(1+G$7)^DCF!$B$17+DCF!$C$16/(1+G$7)^DCF!$C$17+DCF!$D$16/(1+G$7)^DCF!$D$17+DCF!$E$16/(1+G$7)^DCF!$E$17+DCF!$F$16/(1+G$7)^DCF!$F$17+DCF!$F$16*(1+$B13)/(G$7-$B13)/(1+G$7)^5+DCF!$B$9)/DCF!$B$10*DCF!$B$11 | H13: =(DCF!$B$16/(1+H$7)^DCF!$B$17+DCF!$C$16/(1+H$7)^DCF!$C$17+DCF!$D$16/(1+H$7)^DCF!$D$17+DCF!$E$16/(1+H$7)^DCF!$E$17+DCF!$F$16/(1+H$7)^DCF!$F$17+DCF!$F$16*(1+$B13)/(H$7-$B13)/(1+H$7)^5+DCF!$B$9)/DCF!$B$10*DCF!$B$11 | I13: =(DCF!$B$16/(1+I$7)^DCF!$B$17+DCF!$C$16/(1+I$7)^DCF!$C$17+DCF!$D$16/(1+I$7)^DCF!$D$17+DCF!$E$16/(1+I$7)^DCF!$E$17+DCF!$F$16/(1+I$7)^DCF!$F$17+DCF!$F$16*(1+$B13)/(I$7-$B13)/(1+I$7)^5+DCF!$B$9)/DCF!$B$10*DCF!$B$11
B14: =DCF!$B$6+0.0075 | C14: =(DCF!$B$16/(1+C$7)^DCF!$B$17+DCF!$C$16/(1+C$7)^DCF!$C$17+DCF!$D$16/(1+C$7)^DCF!$D$17+DCF!$E$16/(1+C$7)^DCF!$E$17+DCF!$F$16/(1+C$7)^DCF!$F$17+DCF!$F$16*(1+$B14)/(C$7-$B14)/(1+C$7)^5+DCF!$B$9)/DCF!$B$10*DCF!$B$11 | D14: =(DCF!$B$16/(1+D$7)^DCF!$B$17+DCF!$C$16/(1+D$7)^DCF!$C$17+DCF!$D$16/(1+D$7)^DCF!$D$17+DCF!$E$16/(1+D$7)^DCF!$E$17+DCF!$F$16/(1+D$7)^DCF!$F$17+DCF!$F$16*(1+$B14)/(D$7-$B14)/(1+D$7)^5+DCF!$B$9)/DCF!$B$10*DCF!$B$11 | E14: =(DCF!$B$16/(1+E$7)^DCF!$B$17+DCF!$C$16/(1+E$7)^DCF!$C$17+DCF!$D$16/(1+E$7)^DCF!$D$17+DCF!$E$16/(1+E$7)^DCF!$E$17+DCF!$F$16/(1+E$7)^DCF!$F$17+DCF!$F$16*(1+$B14)/(E$7-$B14)/(1+E$7)^5+DCF!$B$9)/DCF!$B$10*DCF!$B$11 | F14: =(DCF!$B$16/(1+F$7)^DCF!$B$17+DCF!$C$16/(1+F$7)^DCF!$C$17+DCF!$D$16/(1+F$7)^DCF!$D$17+DCF!$E$16/(1+F$7)^DCF!$E$17+DCF!$F$16/(1+F$7)^DCF!$F$17+DCF!$F$16*(1+$B14)/(F$7-$B14)/(1+F$7)^5+DCF!$B$9)/DCF!$B$10*DCF!$B$11 | G14: =(DCF!$B$16/(1+G$7)^DCF!$B$17+DCF!$C$16/(1+G$7)^DCF!$C$17+DCF!$D$16/(1+G$7)^DCF!$D$17+DCF!$E$16/(1+G$7)^DCF!$E$17+DCF!$F$16/(1+G$7)^DCF!$F$17+DCF!$F$16*(1+$B14)/(G$7-$B14)/(1+G$7)^5+DCF!$B$9)/DCF!$B$10*DCF!$B$11 | H14: =(DCF!$B$16/(1+H$7)^DCF!$B$17+DCF!$C$16/(1+H$7)^DCF!$C$17+DCF!$D$16/(1+H$7)^DCF!$D$17+DCF!$E$16/(1+H$7)^DCF!$E$17+DCF!$F$16/(1+H$7)^DCF!$F$17+DCF!$F$16*(1+$B14)/(H$7-$B14)/(1+H$7)^5+DCF!$B$9)/DCF!$B$10*DCF!$B$11 | I14: =(DCF!$B$16/(1+I$7)^DCF!$B$17+DCF!$C$16/(1+I$7)^DCF!$C$17+DCF!$D$16/(1+I$7)^DCF!$D$17+DCF!$E$16/(1+I$7)^DCF!$E$17+DCF!$F$16/(1+I$7)^DCF!$F$17+DCF!$F$16*(1+$B14)/(I$7-$B14)/(1+I$7)^5+DCF!$B$9)/DCF!$B$10*DCF!$B$11
B15: Read it as: at a 9.5% WACC and 2.0% terminal growth, the model is worth this many DKK per share.
A16: TABLE 2 — UPSIDE / (DOWNSIDE) vs CURRENT SHARE PRICE
B17: g \ WACC | C17: =DCF!$B$5-0.0075 | D17: =DCF!$B$5-0.0050 | E17: =DCF!$B$5-0.0025 | F17: =DCF!$B$5+0.0000 | G17: =DCF!$B$5+0.0025 | H17: =DCF!$B$5+0.0050 | I17: =DCF!$B$5+0.0075
B18: =DCF!$B$6-0.0075 | C18: =C8/DCF!$B$12-1 | D18: =D8/DCF!$B$12-1 | E18: =E8/DCF!$B$12-1 | F18: =F8/DCF!$B$12-1 | G18: =G8/DCF!$B$12-1 | H18: =H8/DCF!$B$12-1 | I18: =I8/DCF!$B$12-1
B19: =DCF!$B$6-0.0050 | C19: =C9/DCF!$B$12-1 | D19: =D9/DCF!$B$12-1 | E19: =E9/DCF!$B$12-1 | F19: =F9/DCF!$B$12-1 | G19: =G9/DCF!$B$12-1 | H19: =H9/DCF!$B$12-1 | I19: =I9/DCF!$B$12-1
B20: =DCF!$B$6-0.0025 | C20: =C10/DCF!$B$12-1 | D20: =D10/DCF!$B$12-1 | E20: =E10/DCF!$B$12-1 | F20: =F10/DCF!$B$12-1 | G20: =G10/DCF!$B$12-1 | H20: =H10/DCF!$B$12-1 | I20: =I10/DCF!$B$12-1
B21: =DCF!$B$6+0.0000 | C21: =C11/DCF!$B$12-1 | D21: =D11/DCF!$B$12-1 | E21: =E11/DCF!$B$12-1 | F21: =F11/DCF!$B$12-1 | G21: =G11/DCF!$B$12-1 | H21: =H11/DCF!$B$12-1 | I21: =I11/DCF!$B$12-1
B22: =DCF!$B$6+0.0025 | C22: =C12/DCF!$B$12-1 | D22: =D12/DCF!$B$12-1 | E22: =E12/DCF!$B$12-1 | F22: =F12/DCF!$B$12-1 | G22: =G12/DCF!$B$12-1 | H22: =H12/DCF!$B$12-1 | I22: =I12/DCF!$B$12-1
B23: =DCF!$B$6+0.0050 | C23: =C13/DCF!$B$12-1 | D23: =D13/DCF!$B$12-1 | E23: =E13/DCF!$B$12-1 | F23: =F13/DCF!$B$12-1 | G23: =G13/DCF!$B$12-1 | H23: =H13/DCF!$B$12-1 | I23: =I13/DCF!$B$12-1
B24: =DCF!$B$6+0.0075 | C24: =C14/DCF!$B$12-1 | D24: =D14/DCF!$B$12-1 | E24: =E14/DCF!$B$12-1 | F24: =F14/DCF!$B$12-1 | G24: =G14/DCF!$B$12-1 | H24: =H14/DCF!$B$12-1 | I24: =I14/DCF!$B$12-1
B25: Green = the model says the share is cheap. Red = expensive. This is the table that goes in the memo.
A26: TABLE 3 — IMPLIED SHARE PRICE (DKK): WACC (across) x EXIT EV/EBITDA MULTIPLE (down)
B27: Exit x \ WACC | C27: =DCF!$B$5-0.0075 | D27: =DCF!$B$5-0.0050 | E27: =DCF!$B$5-0.0025 | F27: =DCF!$B$5+0.0000 | G27: =DCF!$B$5+0.0025 | H27: =DCF!$B$5+0.0050 | I27: =DCF!$B$5+0.0075
B28: 8.5 | C28: =(DCF!$B$16/(1+C$27)^DCF!$B$17+DCF!$C$16/(1+C$27)^DCF!$C$17+DCF!$D$16/(1+C$27)^DCF!$D$17+DCF!$E$16/(1+C$27)^DCF!$E$17+DCF!$F$16/(1+C$27)^DCF!$F$17+'P&L'!$G$13*$B28/(1+C$27)^5+DCF!$B$9)/DCF!$B$10*DCF!$B$11 | D28: =(DCF!$B$16/(1+D$27)^DCF!$B$17+DCF!$C$16/(1+D$27)^DCF!$C$17+DCF!$D$16/(1+D$27)^DCF!$D$17+DCF!$E$16/(1+D$27)^DCF!$E$17+DCF!$F$16/(1+D$27)^DCF!$F$17+'P&L'!$G$13*$B28/(1+D$27)^5+DCF!$B$9)/DCF!$B$10*DCF!$B$11 | E28: =(DCF!$B$16/(1+E$27)^DCF!$B$17+DCF!$C$16/(1+E$27)^DCF!$C$17+DCF!$D$16/(1+E$27)^DCF!$D$17+DCF!$E$16/(1+E$27)^DCF!$E$17+DCF!$F$16/(1+E$27)^DCF!$F$17+'P&L'!$G$13*$B28/(1+E$27)^5+DCF!$B$9)/DCF!$B$10*DCF!$B$11 | F28: =(DCF!$B$16/(1+F$27)^DCF!$B$17+DCF!$C$16/(1+F$27)^DCF!$C$17+DCF!$D$16/(1+F$27)^DCF!$D$17+DCF!$E$16/(1+F$27)^DCF!$E$17+DCF!$F$16/(1+F$27)^DCF!$F$17+'P&L'!$G$13*$B28/(1+F$27)^5+DCF!$B$9)/DCF!$B$10*DCF!$B$11 | G28: =(DCF!$B$16/(1+G$27)^DCF!$B$17+DCF!$C$16/(1+G$27)^DCF!$C$17+DCF!$D$16/(1+G$27)^DCF!$D$17+DCF!$E$16/(1+G$27)^DCF!$E$17+DCF!$F$16/(1+G$27)^DCF!$F$17+'P&L'!$G$13*$B28/(1+G$27)^5+DCF!$B$9)/DCF!$B$10*DCF!$B$11 | H28: =(DCF!$B$16/(1+H$27)^DCF!$B$17+DCF!$C$16/(1+H$27)^DCF!$C$17+DCF!$D$16/(1+H$27)^DCF!$D$17+DCF!$E$16/(1+H$27)^DCF!$E$17+DCF!$F$16/(1+H$27)^DCF!$F$17+'P&L'!$G$13*$B28/(1+H$27)^5+DCF!$B$9)/DCF!$B$10*DCF!$B$11 | I28: =(DCF!$B$16/(1+I$27)^DCF!$B$17+DCF!$C$16/(1+I$27)^DCF!$C$17+DCF!$D$16/(1+I$27)^DCF!$D$17+DCF!$E$16/(1+I$27)^DCF!$E$17+DCF!$F$16/(1+I$27)^DCF!$F$17+'P&L'!$G$13*$B28/(1+I$27)^5+DCF!$B$9)/DCF!$B$10*DCF!$B$11
B29: 9 | C29: =(DCF!$B$16/(1+C$27)^DCF!$B$17+DCF!$C$16/(1+C$27)^DCF!$C$17+DCF!$D$16/(1+C$27)^DCF!$D$17+DCF!$E$16/(1+C$27)^DCF!$E$17+DCF!$F$16/(1+C$27)^DCF!$F$17+'P&L'!$G$13*$B29/(1+C$27)^5+DCF!$B$9)/DCF!$B$10*DCF!$B$11 | D29: =(DCF!$B$16/(1+D$27)^DCF!$B$17+DCF!$C$16/(1+D$27)^DCF!$C$17+DCF!$D$16/(1+D$27)^DCF!$D$17+DCF!$E$16/(1+D$27)^DCF!$E$17+DCF!$F$16/(1+D$27)^DCF!$F$17+'P&L'!$G$13*$B29/(1+D$27)^5+DCF!$B$9)/DCF!$B$10*DCF!$B$11 | E29: =(DCF!$B$16/(1+E$27)^DCF!$B$17+DCF!$C$16/(1+E$27)^DCF!$C$17+DCF!$D$16/(1+E$27)^DCF!$D$17+DCF!$E$16/(1+E$27)^DCF!$E$17+DCF!$F$16/(1+E$27)^DCF!$F$17+'P&L'!$G$13*$B29/(1+E$27)^5+DCF!$B$9)/DCF!$B$10*DCF!$B$11 | F29: =(DCF!$B$16/(1+F$27)^DCF!$B$17+DCF!$C$16/(1+F$27)^DCF!$C$17+DCF!$D$16/(1+F$27)^DCF!$D$17+DCF!$E$16/(1+F$27)^DCF!$E$17+DCF!$F$16/(1+F$27)^DCF!$F$17+'P&L'!$G$13*$B29/(1+F$27)^5+DCF!$B$9)/DCF!$B$10*DCF!$B$11 | G29: =(DCF!$B$16/(1+G$27)^DCF!$B$17+DCF!$C$16/(1+G$27)^DCF!$C$17+DCF!$D$16/(1+G$27)^DCF!$D$17+DCF!$E$16/(1+G$27)^DCF!$E$17+DCF!$F$16/(1+G$27)^DCF!$F$17+'P&L'!$G$13*$B29/(1+G$27)^5+DCF!$B$9)/DCF!$B$10*DCF!$B$11 | H29: =(DCF!$B$16/(1+H$27)^DCF!$B$17+DCF!$C$16/(1+H$27)^DCF!$C$17+DCF!$D$16/(1+H$27)^DCF!$D$17+DCF!$E$16/(1+H$27)^DCF!$E$17+DCF!$F$16/(1+H$27)^DCF!$F$17+'P&L'!$G$13*$B29/(1+H$27)^5+DCF!$B$9)/DCF!$B$10*DCF!$B$11 | I29: =(DCF!$B$16/(1+I$27)^DCF!$B$17+DCF!$C$16/(1+I$27)^DCF!$C$17+DCF!$D$16/(1+I$27)^DCF!$D$17+DCF!$E$16/(1+I$27)^DCF!$E$17+DCF!$F$16/(1+I$27)^DCF!$F$17+'P&L'!$G$13*$B29/(1+I$27)^5+DCF!$B$9)/DCF!$B$10*DCF!$B$11
B30: 9.5 | C30: =(DCF!$B$16/(1+C$27)^DCF!$B$17+DCF!$C$16/(1+C$27)^DCF!$C$17+DCF!$D$16/(1+C$27)^DCF!$D$17+DCF!$E$16/(1+C$27)^DCF!$E$17+DCF!$F$16/(1+C$27)^DCF!$F$17+'P&L'!$G$13*$B30/(1+C$27)^5+DCF!$B$9)/DCF!$B$10*DCF!$B$11 | D30: =(DCF!$B$16/(1+D$27)^DCF!$B$17+DCF!$C$16/(1+D$27)^DCF!$C$17+DCF!$D$16/(1+D$27)^DCF!$D$17+DCF!$E$16/(1+D$27)^DCF!$E$17+DCF!$F$16/(1+D$27)^DCF!$F$17+'P&L'!$G$13*$B30/(1+D$27)^5+DCF!$B$9)/DCF!$B$10*DCF!$B$11 | E30: =(DCF!$B$16/(1+E$27)^DCF!$B$17+DCF!$C$16/(1+E$27)^DCF!$C$17+DCF!$D$16/(1+E$27)^DCF!$D$17+DCF!$E$16/(1+E$27)^DCF!$E$17+DCF!$F$16/(1+E$27)^DCF!$F$17+'P&L'!$G$13*$B30/(1+E$27)^5+DCF!$B$9)/DCF!$B$10*DCF!$B$11 | F30: =(DCF!$B$16/(1+F$27)^DCF!$B$17+DCF!$C$16/(1+F$27)^DCF!$C$17+DCF!$D$16/(1+F$27)^DCF!$D$17+DCF!$E$16/(1+F$27)^DCF!$E$17+DCF!$F$16/(1+F$27)^DCF!$F$17+'P&L'!$G$13*$B30/(1+F$27)^5+DCF!$B$9)/DCF!$B$10*DCF!$B$11 | G30: =(DCF!$B$16/(1+G$27)^DCF!$B$17+DCF!$C$16/(1+G$27)^DCF!$C$17+DCF!$D$16/(1+G$27)^DCF!$D$17+DCF!$E$16/(1+G$27)^DCF!$E$17+DCF!$F$16/(1+G$27)^DCF!$F$17+'P&L'!$G$13*$B30/(1+G$27)^5+DCF!$B$9)/DCF!$B$10*DCF!$B$11 | H30: =(DCF!$B$16/(1+H$27)^DCF!$B$17+DCF!$C$16/(1+H$27)^DCF!$C$17+DCF!$D$16/(1+H$27)^DCF!$D$17+DCF!$E$16/(1+H$27)^DCF!$E$17+DCF!$F$16/(1+H$27)^DCF!$F$17+'P&L'!$G$13*$B30/(1+H$27)^5+DCF!$B$9)/DCF!$B$10*DCF!$B$11 | I30: =(DCF!$B$16/(1+I$27)^DCF!$B$17+DCF!$C$16/(1+I$27)^DCF!$C$17+DCF!$D$16/(1+I$27)^DCF!$D$17+DCF!$E$16/(1+I$27)^DCF!$E$17+DCF!$F$16/(1+I$27)^DCF!$F$17+'P&L'!$G$13*$B30/(1+I$27)^5+DCF!$B$9)/DCF!$B$10*DCF!$B$11
B31: 10 | C31: =(DCF!$B$16/(1+C$27)^DCF!$B$17+DCF!$C$16/(1+C$27)^DCF!$C$17+DCF!$D$16/(1+C$27)^DCF!$D$17+DCF!$E$16/(1+C$27)^DCF!$E$17+DCF!$F$16/(1+C$27)^DCF!$F$17+'P&L'!$G$13*$B31/(1+C$27)^5+DCF!$B$9)/DCF!$B$10*DCF!$B$11 | D31: =(DCF!$B$16/(1+D$27)^DCF!$B$17+DCF!$C$16/(1+D$27)^DCF!$C$17+DCF!$D$16/(1+D$27)^DCF!$D$17+DCF!$E$16/(1+D$27)^DCF!$E$17+DCF!$F$16/(1+D$27)^DCF!$F$17+'P&L'!$G$13*$B31/(1+D$27)^5+DCF!$B$9)/DCF!$B$10*DCF!$B$11 | E31: =(DCF!$B$16/(1+E$27)^DCF!$B$17+DCF!$C$16/(1+E$27)^DCF!$C$17+DCF!$D$16/(1+E$27)^DCF!$D$17+DCF!$E$16/(1+E$27)^DCF!$E$17+DCF!$F$16/(1+E$27)^DCF!$F$17+'P&L'!$G$13*$B31/(1+E$27)^5+DCF!$B$9)/DCF!$B$10*DCF!$B$11 | F31: =(DCF!$B$16/(1+F$27)^DCF!$B$17+DCF!$C$16/(1+F$27)^DCF!$C$17+DCF!$D$16/(1+F$27)^DCF!$D$17+DCF!$E$16/(1+F$27)^DCF!$E$17+DCF!$F$16/(1+F$27)^DCF!$F$17+'P&L'!$G$13*$B31/(1+F$27)^5+DCF!$B$9)/DCF!$B$10*DCF!$B$11 | G31: =(DCF!$B$16/(1+G$27)^DCF!$B$17+DCF!$C$16/(1+G$27)^DCF!$C$17+DCF!$D$16/(1+G$27)^DCF!$D$17+DCF!$E$16/(1+G$27)^DCF!$E$17+DCF!$F$16/(1+G$27)^DCF!$F$17+'P&L'!$G$13*$B31/(1+G$27)^5+DCF!$B$9)/DCF!$B$10*DCF!$B$11 | H31: =(DCF!$B$16/(1+H$27)^DCF!$B$17+DCF!$C$16/(1+H$27)^DCF!$C$17+DCF!$D$16/(1+H$27)^DCF!$D$17+DCF!$E$16/(1+H$27)^DCF!$E$17+DCF!$F$16/(1+H$27)^DCF!$F$17+'P&L'!$G$13*$B31/(1+H$27)^5+DCF!$B$9)/DCF!$B$10*DCF!$B$11 | I31: =(DCF!$B$16/(1+I$27)^DCF!$B$17+DCF!$C$16/(1+I$27)^DCF!$C$17+DCF!$D$16/(1+I$27)^DCF!$D$17+DCF!$E$16/(1+I$27)^DCF!$E$17+DCF!$F$16/(1+I$27)^DCF!$F$17+'P&L'!$G$13*$B31/(1+I$27)^5+DCF!$B$9)/DCF!$B$10*DCF!$B$11
B32: 10.5 | C32: =(DCF!$B$16/(1+C$27)^DCF!$B$17+DCF!$C$16/(1+C$27)^DCF!$C$17+DCF!$D$16/(1+C$27)^DCF!$D$17+DCF!$E$16/(1+C$27)^DCF!$E$17+DCF!$F$16/(1+C$27)^DCF!$F$17+'P&L'!$G$13*$B32/(1+C$27)^5+DCF!$B$9)/DCF!$B$10*DCF!$B$11 | D32: =(DCF!$B$16/(1+D$27)^DCF!$B$17+DCF!$C$16/(1+D$27)^DCF!$C$17+DCF!$D$16/(1+D$27)^DCF!$D$17+DCF!$E$16/(1+D$27)^DCF!$E$17+DCF!$F$16/(1+D$27)^DCF!$F$17+'P&L'!$G$13*$B32/(1+D$27)^5+DCF!$B$9)/DCF!$B$10*DCF!$B$11 | E32: =(DCF!$B$16/(1+E$27)^DCF!$B$17+DCF!$C$16/(1+E$27)^DCF!$C$17+DCF!$D$16/(1+E$27)^DCF!$D$17+DCF!$E$16/(1+E$27)^DCF!$E$17+DCF!$F$16/(1+E$27)^DCF!$F$17+'P&L'!$G$13*$B32/(1+E$27)^5+DCF!$B$9)/DCF!$B$10*DCF!$B$11 | F32: =(DCF!$B$16/(1+F$27)^DCF!$B$17+DCF!$C$16/(1+F$27)^DCF!$C$17+DCF!$D$16/(1+F$27)^DCF!$D$17+DCF!$E$16/(1+F$27)^DCF!$E$17+DCF!$F$16/(1+F$27)^DCF!$F$17+'P&L'!$G$13*$B32/(1+F$27)^5+DCF!$B$9)/DCF!$B$10*DCF!$B$11 | G32: =(DCF!$B$16/(1+G$27)^DCF!$B$17+DCF!$C$16/(1+G$27)^DCF!$C$17+DCF!$D$16/(1+G$27)^DCF!$D$17+DCF!$E$16/(1+G$27)^DCF!$E$17+DCF!$F$16/(1+G$27)^DCF!$F$17+'P&L'!$G$13*$B32/(1+G$27)^5+DCF!$B$9)/DCF!$B$10*DCF!$B$11 | H32: =(DCF!$B$16/(1+H$27)^DCF!$B$17+DCF!$C$16/(1+H$27)^DCF!$C$17+DCF!$D$16/(1+H$27)^DCF!$D$17+DCF!$E$16/(1+H$27)^DCF!$E$17+DCF!$F$16/(1+H$27)^DCF!$F$17+'P&L'!$G$13*$B32/(1+H$27)^5+DCF!$B$9)/DCF!$B$10*DCF!$B$11 | I32: =(DCF!$B$16/(1+I$27)^DCF!$B$17+DCF!$C$16/(1+I$27)^DCF!$C$17+DCF!$D$16/(1+I$27)^DCF!$D$17+DCF!$E$16/(1+I$27)^DCF!$E$17+DCF!$F$16/(1+I$27)^DCF!$F$17+'P&L'!$G$13*$B32/(1+I$27)^5+DCF!$B$9)/DCF!$B$10*DCF!$B$11
B33: 11 | C33: =(DCF!$B$16/(1+C$27)^DCF!$B$17+DCF!$C$16/(1+C$27)^DCF!$C$17+DCF!$D$16/(1+C$27)^DCF!$D$17+DCF!$E$16/(1+C$27)^DCF!$E$17+DCF!$F$16/(1+C$27)^DCF!$F$17+'P&L'!$G$13*$B33/(1+C$27)^5+DCF!$B$9)/DCF!$B$10*DCF!$B$11 | D33: =(DCF!$B$16/(1+D$27)^DCF!$B$17+DCF!$C$16/(1+D$27)^DCF!$C$17+DCF!$D$16/(1+D$27)^DCF!$D$17+DCF!$E$16/(1+D$27)^DCF!$E$17+DCF!$F$16/(1+D$27)^DCF!$F$17+'P&L'!$G$13*$B33/(1+D$27)^5+DCF!$B$9)/DCF!$B$10*DCF!$B$11 | E33: =(DCF!$B$16/(1+E$27)^DCF!$B$17+DCF!$C$16/(1+E$27)^DCF!$C$17+DCF!$D$16/(1+E$27)^DCF!$D$17+DCF!$E$16/(1+E$27)^DCF!$E$17+DCF!$F$16/(1+E$27)^DCF!$F$17+'P&L'!$G$13*$B33/(1+E$27)^5+DCF!$B$9)/DCF!$B$10*DCF!$B$11 | F33: =(DCF!$B$16/(1+F$27)^DCF!$B$17+DCF!$C$16/(1+F$27)^DCF!$C$17+DCF!$D$16/(1+F$27)^DCF!$D$17+DCF!$E$16/(1+F$27)^DCF!$E$17+DCF!$F$16/(1+F$27)^DCF!$F$17+'P&L'!$G$13*$B33/(1+F$27)^5+DCF!$B$9)/DCF!$B$10*DCF!$B$11 | G33: =(DCF!$B$16/(1+G$27)^DCF!$B$17+DCF!$C$16/(1+G$27)^DCF!$C$17+DCF!$D$16/(1+G$27)^DCF!$D$17+DCF!$E$16/(1+G$27)^DCF!$E$17+DCF!$F$16/(1+G$27)^DCF!$F$17+'P&L'!$G$13*$B33/(1+G$27)^5+DCF!$B$9)/DCF!$B$10*DCF!$B$11 | H33: =(DCF!$B$16/(1+H$27)^DCF!$B$17+DCF!$C$16/(1+H$27)^DCF!$C$17+DCF!$D$16/(1+H$27)^DCF!$D$17+DCF!$E$16/(1+H$27)^DCF!$E$17+DCF!$F$16/(1+H$27)^DCF!$F$17+'P&L'!$G$13*$B33/(1+H$27)^5+DCF!$B$9)/DCF!$B$10*DCF!$B$11 | I33: =(DCF!$B$16/(1+I$27)^DCF!$B$17+DCF!$C$16/(1+I$27)^DCF!$C$17+DCF!$D$16/(1+I$27)^DCF!$D$17+DCF!$E$16/(1+I$27)^DCF!$E$17+DCF!$F$16/(1+I$27)^DCF!$F$17+'P&L'!$G$13*$B33/(1+I$27)^5+DCF!$B$9)/DCF!$B$10*DCF!$B$11
B34: 11.5 | C34: =(DCF!$B$16/(1+C$27)^DCF!$B$17+DCF!$C$16/(1+C$27)^DCF!$C$17+DCF!$D$16/(1+C$27)^DCF!$D$17+DCF!$E$16/(1+C$27)^DCF!$E$17+DCF!$F$16/(1+C$27)^DCF!$F$17+'P&L'!$G$13*$B34/(1+C$27)^5+DCF!$B$9)/DCF!$B$10*DCF!$B$11 | D34: =(DCF!$B$16/(1+D$27)^DCF!$B$17+DCF!$C$16/(1+D$27)^DCF!$C$17+DCF!$D$16/(1+D$27)^DCF!$D$17+DCF!$E$16/(1+D$27)^DCF!$E$17+DCF!$F$16/(1+D$27)^DCF!$F$17+'P&L'!$G$13*$B34/(1+D$27)^5+DCF!$B$9)/DCF!$B$10*DCF!$B$11 | E34: =(DCF!$B$16/(1+E$27)^DCF!$B$17+DCF!$C$16/(1+E$27)^DCF!$C$17+DCF!$D$16/(1+E$27)^DCF!$D$17+DCF!$E$16/(1+E$27)^DCF!$E$17+DCF!$F$16/(1+E$27)^DCF!$F$17+'P&L'!$G$13*$B34/(1+E$27)^5+DCF!$B$9)/DCF!$B$10*DCF!$B$11 | F34: =(DCF!$B$16/(1+F$27)^DCF!$B$17+DCF!$C$16/(1+F$27)^DCF!$C$17+DCF!$D$16/(1+F$27)^DCF!$D$17+DCF!$E$16/(1+F$27)^DCF!$E$17+DCF!$F$16/(1+F$27)^DCF!$F$17+'P&L'!$G$13*$B34/(1+F$27)^5+DCF!$B$9)/DCF!$B$10*DCF!$B$11 | G34: =(DCF!$B$16/(1+G$27)^DCF!$B$17+DCF!$C$16/(1+G$27)^DCF!$C$17+DCF!$D$16/(1+G$27)^DCF!$D$17+DCF!$E$16/(1+G$27)^DCF!$E$17+DCF!$F$16/(1+G$27)^DCF!$F$17+'P&L'!$G$13*$B34/(1+G$27)^5+DCF!$B$9)/DCF!$B$10*DCF!$B$11 | H34: =(DCF!$B$16/(1+H$27)^DCF!$B$17+DCF!$C$16/(1+H$27)^DCF!$C$17+DCF!$D$16/(1+H$27)^DCF!$D$17+DCF!$E$16/(1+H$27)^DCF!$E$17+DCF!$F$16/(1+H$27)^DCF!$F$17+'P&L'!$G$13*$B34/(1+H$27)^5+DCF!$B$9)/DCF!$B$10*DCF!$B$11 | I34: =(DCF!$B$16/(1+I$27)^DCF!$B$17+DCF!$C$16/(1+I$27)^DCF!$C$17+DCF!$D$16/(1+I$27)^DCF!$D$17+DCF!$E$16/(1+I$27)^DCF!$E$17+DCF!$F$16/(1+I$27)^DCF!$F$17+'P&L'!$G$13*$B34/(1+I$27)^5+DCF!$B$9)/DCF!$B$10*DCF!$B$11
B35: The exit-multiple method anchors the terminal value to how the market actually prices the sector.
A36: TABLE 4 — EXECUTION RISK: WACC (across) x UNIFORM CHANGE IN FORECAST FCF (down)
B37: FCF delta \ WACC | C37: =DCF!$B$5-0.0075 | D37: =DCF!$B$5-0.0050 | E37: =DCF!$B$5-0.0025 | F37: =DCF!$B$5+0.0000 | G37: =DCF!$B$5+0.0025 | H37: =DCF!$B$5+0.0050 | I37: =DCF!$B$5+0.0075
B38: -0.2 | C38: =((1+$B38)*(DCF!$B$16/(1+C$37)^DCF!$B$17+DCF!$C$16/(1+C$37)^DCF!$C$17+DCF!$D$16/(1+C$37)^DCF!$D$17+DCF!$E$16/(1+C$37)^DCF!$E$17+DCF!$F$16/(1+C$37)^DCF!$F$17+DCF!$F$16*(1+DCF!$B$6)/(C$37-DCF!$B$6)/(1+C$37)^5)+DCF!$B$9)/DCF!$B$10*DCF!$B$11 | D38: =((1+$B38)*(DCF!$B$16/(1+D$37)^DCF!$B$17+DCF!$C$16/(1+D$37)^DCF!$C$17+DCF!$D$16/(1+D$37)^DCF!$D$17+DCF!$E$16/(1+D$37)^DCF!$E$17+DCF!$F$16/(1+D$37)^DCF!$F$17+DCF!$F$16*(1+DCF!$B$6)/(D$37-DCF!$B$6)/(1+D$37)^5)+DCF!$B$9)/DCF!$B$10*DCF!$B$11 | E38: =((1+$B38)*(DCF!$B$16/(1+E$37)^DCF!$B$17+DCF!$C$16/(1+E$37)^DCF!$C$17+DCF!$D$16/(1+E$37)^DCF!$D$17+DCF!$E$16/(1+E$37)^DCF!$E$17+DCF!$F$16/(1+E$37)^DCF!$F$17+DCF!$F$16*(1+DCF!$B$6)/(E$37-DCF!$B$6)/(1+E$37)^5)+DCF!$B$9)/DCF!$B$10*DCF!$B$11 | F38: =((1+$B38)*(DCF!$B$16/(1+F$37)^DCF!$B$17+DCF!$C$16/(1+F$37)^DCF!$C$17+DCF!$D$16/(1+F$37)^DCF!$D$17+DCF!$E$16/(1+F$37)^DCF!$E$17+DCF!$F$16/(1+F$37)^DCF!$F$17+DCF!$F$16*(1+DCF!$B$6)/(F$37-DCF!$B$6)/(1+F$37)^5)+DCF!$B$9)/DCF!$B$10*DCF!$B$11 | G38: =((1+$B38)*(DCF!$B$16/(1+G$37)^DCF!$B$17+DCF!$C$16/(1+G$37)^DCF!$C$17+DCF!$D$16/(1+G$37)^DCF!$D$17+DCF!$E$16/(1+G$37)^DCF!$E$17+DCF!$F$16/(1+G$37)^DCF!$F$17+DCF!$F$16*(1+DCF!$B$6)/(G$37-DCF!$B$6)/(1+G$37)^5)+DCF!$B$9)/DCF!$B$10*DCF!$B$11 | H38: =((1+$B38)*(DCF!$B$16/(1+H$37)^DCF!$B$17+DCF!$C$16/(1+H$37)^DCF!$C$17+DCF!$D$16/(1+H$37)^DCF!$D$17+DCF!$E$16/(1+H$37)^DCF!$E$17+DCF!$F$16/(1+H$37)^DCF!$F$17+DCF!$F$16*(1+DCF!$B$6)/(H$37-DCF!$B$6)/(1+H$37)^5)+DCF!$B$9)/DCF!$B$10*DCF!$B$11 | I38: =((1+$B38)*(DCF!$B$16/(1+I$37)^DCF!$B$17+DCF!$C$16/(1+I$37)^DCF!$C$17+DCF!$D$16/(1+I$37)^DCF!$D$17+DCF!$E$16/(1+I$37)^DCF!$E$17+DCF!$F$16/(1+I$37)^DCF!$F$17+DCF!$F$16*(1+DCF!$B$6)/(I$37-DCF!$B$6)/(1+I$37)^5)+DCF!$B$9)/DCF!$B$10*DCF!$B$11
B39: -0.15 | C39: =((1+$B39)*(DCF!$B$16/(1+C$37)^DCF!$B$17+DCF!$C$16/(1+C$37)^DCF!$C$17+DCF!$D$16/(1+C$37)^DCF!$D$17+DCF!$E$16/(1+C$37)^DCF!$E$17+DCF!$F$16/(1+C$37)^DCF!$F$17+DCF!$F$16*(1+DCF!$B$6)/(C$37-DCF!$B$6)/(1+C$37)^5)+DCF!$B$9)/DCF!$B$10*DCF!$B$11 | D39: =((1+$B39)*(DCF!$B$16/(1+D$37)^DCF!$B$17+DCF!$C$16/(1+D$37)^DCF!$C$17+DCF!$D$16/(1+D$37)^DCF!$D$17+DCF!$E$16/(1+D$37)^DCF!$E$17+DCF!$F$16/(1+D$37)^DCF!$F$17+DCF!$F$16*(1+DCF!$B$6)/(D$37-DCF!$B$6)/(1+D$37)^5)+DCF!$B$9)/DCF!$B$10*DCF!$B$11 | E39: =((1+$B39)*(DCF!$B$16/(1+E$37)^DCF!$B$17+DCF!$C$16/(1+E$37)^DCF!$C$17+DCF!$D$16/(1+E$37)^DCF!$D$17+DCF!$E$16/(1+E$37)^DCF!$E$17+DCF!$F$16/(1+E$37)^DCF!$F$17+DCF!$F$16*(1+DCF!$B$6)/(E$37-DCF!$B$6)/(1+E$37)^5)+DCF!$B$9)/DCF!$B$10*DCF!$B$11 | F39: =((1+$B39)*(DCF!$B$16/(1+F$37)^DCF!$B$17+DCF!$C$16/(1+F$37)^DCF!$C$17+DCF!$D$16/(1+F$37)^DCF!$D$17+DCF!$E$16/(1+F$37)^DCF!$E$17+DCF!$F$16/(1+F$37)^DCF!$F$17+DCF!$F$16*(1+DCF!$B$6)/(F$37-DCF!$B$6)/(1+F$37)^5)+DCF!$B$9)/DCF!$B$10*DCF!$B$11 | G39: =((1+$B39)*(DCF!$B$16/(1+G$37)^DCF!$B$17+DCF!$C$16/(1+G$37)^DCF!$C$17+DCF!$D$16/(1+G$37)^DCF!$D$17+DCF!$E$16/(1+G$37)^DCF!$E$17+DCF!$F$16/(1+G$37)^DCF!$F$17+DCF!$F$16*(1+DCF!$B$6)/(G$37-DCF!$B$6)/(1+G$37)^5)+DCF!$B$9)/DCF!$B$10*DCF!$B$11 | H39: =((1+$B39)*(DCF!$B$16/(1+H$37)^DCF!$B$17+DCF!$C$16/(1+H$37)^DCF!$C$17+DCF!$D$16/(1+H$37)^DCF!$D$17+DCF!$E$16/(1+H$37)^DCF!$E$17+DCF!$F$16/(1+H$37)^DCF!$F$17+DCF!$F$16*(1+DCF!$B$6)/(H$37-DCF!$B$6)/(1+H$37)^5)+DCF!$B$9)/DCF!$B$10*DCF!$B$11 | I39: =((1+$B39)*(DCF!$B$16/(1+I$37)^DCF!$B$17+DCF!$C$16/(1+I$37)^DCF!$C$17+DCF!$D$16/(1+I$37)^DCF!$D$17+DCF!$E$16/(1+I$37)^DCF!$E$17+DCF!$F$16/(1+I$37)^DCF!$F$17+DCF!$F$16*(1+DCF!$B$6)/(I$37-DCF!$B$6)/(1+I$37)^5)+DCF!$B$9)/DCF!$B$10*DCF!$B$11
B40: -0.1 | C40: =((1+$B40)*(DCF!$B$16/(1+C$37)^DCF!$B$17+DCF!$C$16/(1+C$37)^DCF!$C$17+DCF!$D$16/(1+C$37)^DCF!$D$17+DCF!$E$16/(1+C$37)^DCF!$E$17+DCF!$F$16/(1+C$37)^DCF!$F$17+DCF!$F$16*(1+DCF!$B$6)/(C$37-DCF!$B$6)/(1+C$37)^5)+DCF!$B$9)/DCF!$B$10*DCF!$B$11 | D40: =((1+$B40)*(DCF!$B$16/(1+D$37)^DCF!$B$17+DCF!$C$16/(1+D$37)^DCF!$C$17+DCF!$D$16/(1+D$37)^DCF!$D$17+DCF!$E$16/(1+D$37)^DCF!$E$17+DCF!$F$16/(1+D$37)^DCF!$F$17+DCF!$F$16*(1+DCF!$B$6)/(D$37-DCF!$B$6)/(1+D$37)^5)+DCF!$B$9)/DCF!$B$10*DCF!$B$11 | E40: =((1+$B40)*(DCF!$B$16/(1+E$37)^DCF!$B$17+DCF!$C$16/(1+E$37)^DCF!$C$17+DCF!$D$16/(1+E$37)^DCF!$D$17+DCF!$E$16/(1+E$37)^DCF!$E$17+DCF!$F$16/(1+E$37)^DCF!$F$17+DCF!$F$16*(1+DCF!$B$6)/(E$37-DCF!$B$6)/(1+E$37)^5)+DCF!$B$9)/DCF!$B$10*DCF!$B$11 | F40: =((1+$B40)*(DCF!$B$16/(1+F$37)^DCF!$B$17+DCF!$C$16/(1+F$37)^DCF!$C$17+DCF!$D$16/(1+F$37)^DCF!$D$17+DCF!$E$16/(1+F$37)^DCF!$E$17+DCF!$F$16/(1+F$37)^DCF!$F$17+DCF!$F$16*(1+DCF!$B$6)/(F$37-DCF!$B$6)/(1+F$37)^5)+DCF!$B$9)/DCF!$B$10*DCF!$B$11 | G40: =((1+$B40)*(DCF!$B$16/(1+G$37)^DCF!$B$17+DCF!$C$16/(1+G$37)^DCF!$C$17+DCF!$D$16/(1+G$37)^DCF!$D$17+DCF!$E$16/(1+G$37)^DCF!$E$17+DCF!$F$16/(1+G$37)^DCF!$F$17+DCF!$F$16*(1+DCF!$B$6)/(G$37-DCF!$B$6)/(1+G$37)^5)+DCF!$B$9)/DCF!$B$10*DCF!$B$11 | H40: =((1+$B40)*(DCF!$B$16/(1+H$37)^DCF!$B$17+DCF!$C$16/(1+H$37)^DCF!$C$17+DCF!$D$16/(1+H$37)^DCF!$D$17+DCF!$E$16/(1+H$37)^DCF!$E$17+DCF!$F$16/(1+H$37)^DCF!$F$17+DCF!$F$16*(1+DCF!$B$6)/(H$37-DCF!$B$6)/(1+H$37)^5)+DCF!$B$9)/DCF!$B$10*DCF!$B$11 | I40: =((1+$B40)*(DCF!$B$16/(1+I$37)^DCF!$B$17+DCF!$C$16/(1+I$37)^DCF!$C$17+DCF!$D$16/(1+I$37)^DCF!$D$17+DCF!$E$16/(1+I$37)^DCF!$E$17+DCF!$F$16/(1+I$37)^DCF!$F$17+DCF!$F$16*(1+DCF!$B$6)/(I$37-DCF!$B$6)/(1+I$37)^5)+DCF!$B$9)/DCF!$B$10*DCF!$B$11
B41: -0.05 | C41: =((1+$B41)*(DCF!$B$16/(1+C$37)^DCF!$B$17+DCF!$C$16/(1+C$37)^DCF!$C$17+DCF!$D$16/(1+C$37)^DCF!$D$17+DCF!$E$16/(1+C$37)^DCF!$E$17+DCF!$F$16/(1+C$37)^DCF!$F$17+DCF!$F$16*(1+DCF!$B$6)/(C$37-DCF!$B$6)/(1+C$37)^5)+DCF!$B$9)/DCF!$B$10*DCF!$B$11 | D41: =((1+$B41)*(DCF!$B$16/(1+D$37)^DCF!$B$17+DCF!$C$16/(1+D$37)^DCF!$C$17+DCF!$D$16/(1+D$37)^DCF!$D$17+DCF!$E$16/(1+D$37)^DCF!$E$17+DCF!$F$16/(1+D$37)^DCF!$F$17+DCF!$F$16*(1+DCF!$B$6)/(D$37-DCF!$B$6)/(1+D$37)^5)+DCF!$B$9)/DCF!$B$10*DCF!$B$11 | E41: =((1+$B41)*(DCF!$B$16/(1+E$37)^DCF!$B$17+DCF!$C$16/(1+E$37)^DCF!$C$17+DCF!$D$16/(1+E$37)^DCF!$D$17+DCF!$E$16/(1+E$37)^DCF!$E$17+DCF!$F$16/(1+E$37)^DCF!$F$17+DCF!$F$16*(1+DCF!$B$6)/(E$37-DCF!$B$6)/(1+E$37)^5)+DCF!$B$9)/DCF!$B$10*DCF!$B$11 | F41: =((1+$B41)*(DCF!$B$16/(1+F$37)^DCF!$B$17+DCF!$C$16/(1+F$37)^DCF!$C$17+DCF!$D$16/(1+F$37)^DCF!$D$17+DCF!$E$16/(1+F$37)^DCF!$E$17+DCF!$F$16/(1+F$37)^DCF!$F$17+DCF!$F$16*(1+DCF!$B$6)/(F$37-DCF!$B$6)/(1+F$37)^5)+DCF!$B$9)/DCF!$B$10*DCF!$B$11 | G41: =((1+$B41)*(DCF!$B$16/(1+G$37)^DCF!$B$17+DCF!$C$16/(1+G$37)^DCF!$C$17+DCF!$D$16/(1+G$37)^DCF!$D$17+DCF!$E$16/(1+G$37)^DCF!$E$17+DCF!$F$16/(1+G$37)^DCF!$F$17+DCF!$F$16*(1+DCF!$B$6)/(G$37-DCF!$B$6)/(1+G$37)^5)+DCF!$B$9)/DCF!$B$10*DCF!$B$11 | H41: =((1+$B41)*(DCF!$B$16/(1+H$37)^DCF!$B$17+DCF!$C$16/(1+H$37)^DCF!$C$17+DCF!$D$16/(1+H$37)^DCF!$D$17+DCF!$E$16/(1+H$37)^DCF!$E$17+DCF!$F$16/(1+H$37)^DCF!$F$17+DCF!$F$16*(1+DCF!$B$6)/(H$37-DCF!$B$6)/(1+H$37)^5)+DCF!$B$9)/DCF!$B$10*DCF!$B$11 | I41: =((1+$B41)*(DCF!$B$16/(1+I$37)^DCF!$B$17+DCF!$C$16/(1+I$37)^DCF!$C$17+DCF!$D$16/(1+I$37)^DCF!$D$17+DCF!$E$16/(1+I$37)^DCF!$E$17+DCF!$F$16/(1+I$37)^DCF!$F$17+DCF!$F$16*(1+DCF!$B$6)/(I$37-DCF!$B$6)/(1+I$37)^5)+DCF!$B$9)/DCF!$B$10*DCF!$B$11
B42: 0 | C42: =((1+$B42)*(DCF!$B$16/(1+C$37)^DCF!$B$17+DCF!$C$16/(1+C$37)^DCF!$C$17+DCF!$D$16/(1+C$37)^DCF!$D$17+DCF!$E$16/(1+C$37)^DCF!$E$17+DCF!$F$16/(1+C$37)^DCF!$F$17+DCF!$F$16*(1+DCF!$B$6)/(C$37-DCF!$B$6)/(1+C$37)^5)+DCF!$B$9)/DCF!$B$10*DCF!$B$11 | D42: =((1+$B42)*(DCF!$B$16/(1+D$37)^DCF!$B$17+DCF!$C$16/(1+D$37)^DCF!$C$17+DCF!$D$16/(1+D$37)^DCF!$D$17+DCF!$E$16/(1+D$37)^DCF!$E$17+DCF!$F$16/(1+D$37)^DCF!$F$17+DCF!$F$16*(1+DCF!$B$6)/(D$37-DCF!$B$6)/(1+D$37)^5)+DCF!$B$9)/DCF!$B$10*DCF!$B$11 | E42: =((1+$B42)*(DCF!$B$16/(1+E$37)^DCF!$B$17+DCF!$C$16/(1+E$37)^DCF!$C$17+DCF!$D$16/(1+E$37)^DCF!$D$17+DCF!$E$16/(1+E$37)^DCF!$E$17+DCF!$F$16/(1+E$37)^DCF!$F$17+DCF!$F$16*(1+DCF!$B$6)/(E$37-DCF!$B$6)/(1+E$37)^5)+DCF!$B$9)/DCF!$B$10*DCF!$B$11 | F42: =((1+$B42)*(DCF!$B$16/(1+F$37)^DCF!$B$17+DCF!$C$16/(1+F$37)^DCF!$C$17+DCF!$D$16/(1+F$37)^DCF!$D$17+DCF!$E$16/(1+F$37)^DCF!$E$17+DCF!$F$16/(1+F$37)^DCF!$F$17+DCF!$F$16*(1+DCF!$B$6)/(F$37-DCF!$B$6)/(1+F$37)^5)+DCF!$B$9)/DCF!$B$10*DCF!$B$11 | G42: =((1+$B42)*(DCF!$B$16/(1+G$37)^DCF!$B$17+DCF!$C$16/(1+G$37)^DCF!$C$17+DCF!$D$16/(1+G$37)^DCF!$D$17+DCF!$E$16/(1+G$37)^DCF!$E$17+DCF!$F$16/(1+G$37)^DCF!$F$17+DCF!$F$16*(1+DCF!$B$6)/(G$37-DCF!$B$6)/(1+G$37)^5)+DCF!$B$9)/DCF!$B$10*DCF!$B$11 | H42: =((1+$B42)*(DCF!$B$16/(1+H$37)^DCF!$B$17+DCF!$C$16/(1+H$37)^DCF!$C$17+DCF!$D$16/(1+H$37)^DCF!$D$17+DCF!$E$16/(1+H$37)^DCF!$E$17+DCF!$F$16/(1+H$37)^DCF!$F$17+DCF!$F$16*(1+DCF!$B$6)/(H$37-DCF!$B$6)/(1+H$37)^5)+DCF!$B$9)/DCF!$B$10*DCF!$B$11 | I42: =((1+$B42)*(DCF!$B$16/(1+I$37)^DCF!$B$17+DCF!$C$16/(1+I$37)^DCF!$C$17+DCF!$D$16/(1+I$37)^DCF!$D$17+DCF!$E$16/(1+I$37)^DCF!$E$17+DCF!$F$16/(1+I$37)^DCF!$F$17+DCF!$F$16*(1+DCF!$B$6)/(I$37-DCF!$B$6)/(1+I$37)^5)+DCF!$B$9)/DCF!$B$10*DCF!$B$11
...

Sheet Scenarios
A1: SCENARIO ANALYSIS — BEAR / BASE / BULL
A2: Three live parallel models. They do NOT depend on the switch in Assumptions!B7, so all three are visible at once.
A7: BEAR CASE
A8: EUR m | B8: 2026E | C8: 2027E | D8: 2028E | E8: 2029E | F8: 2030E | H8: Valuation
A9: MW delivered | B9: =Assumptions!C45 | C9: =Assumptions!D45 | D9: =Assumptions!E45 | E9: =Assumptions!F45 | F9: =Assumptions!G45
A10: Revenue | B10: =B9*Assumptions!C12+Assumptions!C14 | C10: =C9*Assumptions!D12+Assumptions!D14 | D10: =D9*Assumptions!E12+Assumptions!E14 | E10: =E9*Assumptions!F12+Assumptions!F14 | F10: =F9*Assumptions!G12+Assumptions!G14
A11: Revenue growth % | B11: =B10/Historical!$F$7-1 | C11: =C10/B10-1 | D11: =D10/C10-1 | E11: =E10/D10-1 | F11: =F10/E10-1
A12: Gross margin % | B12: =Assumptions!C48 | C12: =Assumptions!D48 | D12: =Assumptions!E48 | E12: =Assumptions!F48 | F12: =Assumptions!G48
A13: EBITDA | B13: =B10*(B12-Assumptions!C22) | C13: =C10*(C12-Assumptions!D22) | D13: =D10*(D12-Assumptions!E22) | E13: =E10*(E12-Assumptions!F22) | F13: =F10*(F12-Assumptions!G22)
A14: EBIT | B14: =B13-B10*Assumptions!C24 | C14: =C13-C10*Assumptions!D24 | D14: =D13-D10*Assumptions!E24 | E14: =E13-E10*Assumptions!F24 | F14: =F13-F10*Assumptions!G24
A15: EBIT margin % | B15: =B14/B10 | C15: =C14/C10 | D15: =D14/D10 | E15: =E14/E10 | F15: =F14/F10
A16: NOPAT | B16: =B14*(1-Assumptions!C35) | C16: =C14*(1-Assumptions!D35) | D16: =D14*(1-Assumptions!E35) | E16: =E14*(1-Assumptions!F35) | F16: =F14*(1-Assumptions!G35)
A17: (-) Capex | B17: =B10*Assumptions!C29 | C17: =C10*Assumptions!D29 | D17: =D10*Assumptions!E29 | E17: =E10*Assumptions!F29 | F17: =F10*Assumptions!G29
A18: (-) Change in NWC | B18: =B10*Assumptions!C32-Historical!$F$26 | C18: =C10*Assumptions!D32-B10*Assumptions!C32 | D18: =D10*Assumptions!E32-C10*Assumptions!D32 | E18: =E10*Assumptions!F32-D10*Assumptions!E32 | F18: =F10*Assumptions!G32-E10*Assumptions!F32
A19: UNLEVERED FCF | B19: =B16+B10*Assumptions!C24-B17-B18 | C19: =C16+C10*Assumptions!D24-C17-C18 | D19: =D16+D10*Assumptions!E24-D17-D18 | E19: =E16+E10*Assumptions!F24-E17-E18 | F19: =F16+F10*Assumptions!G24-F17-F18
A20: PV of FCF | B20: =B19*DCF!B$18 | C20: =C19*DCF!C$18 | D20: =D19*DCF!D$18 | E20: =E19*DCF!E$18 | F20: =F19*DCF!F$18 | H20: =SUM(B20:F20)
A21: Terminal value (Gordon) | H21: =F19*(1+DCF!$B$6)/(DCF!$B$5-DCF!$B$6)
A22: PV of terminal value | H22: =H21*DCF!$F$24
A23: Enterprise value | H23: =H20+H22
A24: Equity value | H24: =H23+DCF!$B$9
A25: Implied price per share (DKK) | H25: =H24/DCF!$B$10*DCF!$B$11
A26: Upside / (downside) | H26: =H25/DCF!$B$12-1
A28: BASE CASE
A29: EUR m | B29: 2026E | C29: 2027E | D29: 2028E | E29: 2029E | F29: 2030E | H29: Valuation
A30: MW delivered | B30: =Assumptions!C46 | C30: =Assumptions!D46 | D30: =Assumptions!E46 | E30: =Assumptions!F46 | F30: =Assumptions!G46
A31: Revenue | B31: =B30*Assumptions!C12+Assumptions!C14 | C31: =C30*Assumptions!D12+Assumptions!D14 | D31: =D30*Assumptions!E12+Assumptions!E14 | E31: =E30*Assumptions!F12+Assumptions!F14 | F31: =F30*Assumptions!G12+Assumptions!G14
A32: Revenue growth % | B32: =B31/Historical!$F$7-1 | C32: =C31/B31-1 | D32: =D31/C31-1 | E32: =E31/D31-1 | F32: =F31/E31-1
A33: Gross margin % | B33: =Assumptions!C49 | C33: =Assumptions!D49 | D33: =Assumptions!E49 | E33: =Assumptions!F49 | F33: =Assumptions!G49
A34: EBITDA | B34: =B31*(B33-Assumptions!C22) | C34: =C31*(C33-Assumptions!D22) | D34: =D31*(D33-Assumptions!E22) | E34: =E31*(E33-Assumptions!F22) | F34: =F31*(F33-Assumptions!G22)
A35: EBIT | B35: =B34-B31*Assumptions!C24 | C35: =C34-C31*Assumptions!D24 | D35: =D34-D31*Assumptions!E24 | E35: =E34-E31*Assumptions!F24 | F35: =F34-F31*Assumptions!G24
A36: EBIT margin % | B36: =B35/B31 | C36: =C35/C31 | D36: =D35/D31 | E36: =E35/E31 | F36: =F35/F31
A37: NOPAT | B37: =B35*(1-Assumptions!C35) | C37: =C35*(1-Assumptions!D35) | D37: =D35*(1-Assumptions!E35) | E37: =E35*(1-Assumptions!F35) | F37: =F35*(1-Assumptions!G35)
A38: (-) Capex | B38: =B31*Assumptions!C29 | C38: =C31*Assumptions!D29 | D38: =D31*Assumptions!E29 | E38: =E31*Assumptions!F29 | F38: =F31*Assumptions!G29
A39: (-) Change in NWC | B39: =B31*Assumptions!C32-Historical!$F$26 | C39: =C31*Assumptions!D32-B31*Assumptions!C32 | D39: =D31*Assumptions!E32-C31*Assumptions!D32 | E39: =E31*Assumptions!F32-D31*Assumptions!E32 | F39: =F31*Assumptions!G32-E31*Assumptions!F32
A40: UNLEVERED FCF | B40: =B37+B31*Assumptions!C24-B38-B39 | C40: =C37+C31*Assumptions!D24-C38-C39 | D40: =D37+D31*Assumptions!E24-D38-D39 | E40: =E37+E31*Assumptions!F24-E38-E39 | F40: =F37+F31*Assumptions!G24-F38-F39
A41: PV of FCF | B41: =B40*DCF!B$18 | C41: =C40*DCF!C$18 | D41: =D40*DCF!D$18 | E41: =E40*DCF!E$18 | F41: =F40*DCF!F$18 | H41: =SUM(B41:F41)
A42: Terminal value (Gordon) | H42: =F40*(1+DCF!$B$6)/(DCF!$B$5-DCF!$B$6)
A43: PV of terminal value | H43: =H42*DCF!$F$24
A44: Enterprise value | H44: =H41+H43
A45: Equity value | H45: =H44+DCF!$B$9
...

Sheet Comps
A1: TRADING COMPARABLES
A2: Peer set is deliberately small and honest. Add GE Vernova, Goldwind and TPI Composites when you can source clean data.
A4: Company | B4: Ticker | C4: Price (local) | D4: FX/EUR | E4: Shares (m) | F4: Mkt cap (EURm) | G4: Net debt/(cash) | H4: EV (EURm) | I4: Revenue TTM | J4: EBITDA TTM | K4: EV/Rev | L4: EV/EBITDA | M4: P/E | N4: Fwd P/E | O4: Data as of
A5: Vestas Wind Systems | B5: CPH:VWS | C5: 204.5 | D5: 7.46 | E5: 982.6 | F5: =C5*E5/D5 | G5: -1174 | H5: =F5+G5 | I5: 20342 | J5: 2091 | K5: =H5/I5 | L5: =H5/J5 | M5: 25.67 | N5: 18.73 | O5: 14-Aug-2026
A6: Nordex SE | B6: ETR:NDX1 | C6: 40.62 | D6: 1 | E6: 238.1 | F6: =C6*E6/D6 | G6: -1360 | H6: =F6+G6 | I6: 7710 | J6: 702 | K6: =H6/I6 | L6: =H6/J6 | M6: 31.58 | N6: 17.24 | O6: 05-Jun-2026
A7: Siemens Energy AG | B7: ETR:ENR | C7: 152.58 | D7: 1 | E7: 865.2 | F7: =C7*E7/D7 | G7: -8130 | H7: =F7+G7 | I7: 41840 | J7: 4610 | K7: =H7/I7 | L7: =H7/J7 | M7: 50.2 | N7: 25.95 | O7: 20-Aug-2026
A9: Median (peers excl. Vestas) | K9: =MEDIAN(K6:K7) | L9: =MEDIAN(L6:L7) | M9: =MEDIAN(M6:M7) | N9: =MEDIAN(N6:N7)
A10: Vestas premium / (discount) to peer median (EV/EBITDA) | L10: =L5/L9-1
A11: WARNING | B11: Siemens Energy is a diversified energy-technology group (gas turbines, grid), not a pure wind OEM. Two peers is not a comp set - it is a starting point.
A13: IMPLIED VALUATION FOR VESTAS — EV / EBITDA
B14: Low | C14: Mid | D14: High
A15: EV/EBITDA multiple applied | B15: 8.5 | C15: 10 | D15: 11.5
A16: Vestas 2026E EBITDA (EUR m) | B16: ='P&L'!$C$13 | C16: ='P&L'!$C$13 | D16: ='P&L'!$C$13
A17: Implied enterprise value | B17: =B15*B16 | C17: =C15*C16 | D17: =D15*D16
A18: (+) Net cash / (-) net debt | B18: =DCF!$B$9 | C18: =DCF!$B$9 | D18: =DCF!$B$9
A19: Implied equity value | B19: =B17+B18 | C19: =C17+C18 | D19: =D17+D18
A20: Implied price per share (DKK) | B20: =B19/DCF!$B$10*DCF!$B$11 | C20: =C19/DCF!$B$10*DCF!$B$11 | D20: =D19/DCF!$B$10*DCF!$B$11
A21: Upside / (downside) | B21: =B20/DCF!$B$12-1 | C21: =C20/DCF!$B$12-1 | D21: =D20/DCF!$B$12-1
A23: IMPLIED VALUATION FOR VESTAS — EV / REVENUE
B24: Low | C24: Mid | D24: High
A25: EV/Revenue multiple applied | B25: 0.95 | C25: 1.2 | D25: 1.45
A26: Vestas 2026E revenue (EUR m) | B26: ='P&L'!$C$7 | C26: ='P&L'!$C$7 | D26: ='P&L'!$C$7
A27: Implied enterprise value | B27: =B25*B26 | C27: =C25*C26 | D27: =D25*D26
A28: (+) Net cash / (-) net debt | B28: =DCF!$B$9 | C28: =DCF!$B$9 | D28: =DCF!$B$9
A29: Implied equity value | B29: =B27+B28 | C29: =C27+C28 | D29: =D27+D28
A30: Implied price per share (DKK) | B30: =B29/DCF!$B$10*DCF!$B$11 | C30: =C29/DCF!$B$10*DCF!$B$11 | D30: =D29/DCF!$B$10*DCF!$B$11
A31: Upside / (downside) | B31: =B30/DCF!$B$12-1 | C31: =C30/DCF!$B$12-1 | D31: =D30/DCF!$B$12-1

Sheet P&L
A1: INCOME STATEMENT — 2025A and 2026E-2030E
A2: All lines are formulas driven by the Assumptions sheet. No hardcodes on this page.
A4: EUR m | B4: 2025A | C4: 2026E | D4: 2027E | E4: 2028E | F4: 2029E | G4: 2030E | H4: Comment
A6: INCOME STATEMENT
A7: Revenue | B7: =Assumptions!B16 | C7: =Assumptions!C16 | D7: =Assumptions!D16 | E7: =Assumptions!E16 | F7: =Assumptions!F16 | G7: =Assumptions!G16
A8: Revenue growth % | C8: =C7/B7-1 | D8: =D7/C7-1 | E8: =E7/D7-1 | F8: =F7/E7-1 | G8: =G7/F7-1
A9: Cost of goods sold | B9: =B7*(1-Assumptions!B21) | C9: =C7*(1-Assumptions!C21) | D9: =D7*(1-Assumptions!D21) | E9: =E7*(1-Assumptions!E21) | F9: =F7*(1-Assumptions!F21) | G9: =G7*(1-Assumptions!G21)
A10: Gross profit | B10: =B7-B9 | C10: =C7-C9 | D10: =D7-D9 | E10: =E7-E9 | F10: =F7-F9 | G10: =G7-G9
A11: Gross margin % | B11: =B10/B7 | C11: =C10/C7 | D11: =D10/D7 | E11: =E10/E7 | F11: =F10/F7 | G11: =G10/G7
A12: Operating expenses | B12: =B7*Assumptions!B22 | C12: =C7*Assumptions!C22 | D12: =D7*Assumptions!D22 | E12: =E7*Assumptions!E22 | F12: =F7*Assumptions!F22 | G12: =G7*Assumptions!G22
A13: EBITDA | B13: =B10-B12 | C13: =C10-C12 | D13: =D10-D12 | E13: =E10-E12 | F13: =F10-F12 | G13: =G10-G12
A14: EBITDA margin % | B14: =B13/B7 | C14: =C13/C7 | D14: =D13/D7 | E14: =E13/E7 | F14: =F13/F7 | G14: =G13/G7
A15: Depreciation & amortisation | B15: =B7*Assumptions!B24 | C15: =C7*Assumptions!C24 | D15: =D7*Assumptions!D24 | E15: =E7*Assumptions!E24 | F15: =F7*Assumptions!F24 | G15: =G7*Assumptions!G24
A16: EBIT | B16: =B13-B15 | C16: =C13-C15 | D16: =D13-D15 | E16: =E13-E15 | F16: =F13-F15 | G16: =G13-G15
A17: EBIT margin % | B17: =B16/B7 | C17: =C16/C7 | D17: =D16/D7 | E17: =E16/E7 | F17: =F16/F7 | G17: =G16/G7
A18: Tax on EBIT (unlevered) | B18: =B16*Assumptions!B35 | C18: =C16*Assumptions!C35 | D18: =D16*Assumptions!D35 | E18: =E16*Assumptions!E35 | F18: =F16*Assumptions!F35 | G18: =G16*Assumptions!G35 | H18: Tax on EBIT, NOT on pre-tax profit. A DCF values the firm, not the equity.
A19: NOPAT (EBIAT) | B19: =B16-B18 | C19: =C16-C18 | D19: =D16-D18 | E19: =E16-E18 | F19: =F16-F18 | G19: =G16-G18
A21: MEMO ITEMS
A22: Service revenue as % of total | B22: =Assumptions!B14/Assumptions!B16 | C22: =Assumptions!C14/Assumptions!C16 | D22: =Assumptions!D14/Assumptions!D16 | E22: =Assumptions!E14/Assumptions!E16 | F22: =Assumptions!F14/Assumptions!F16 | G22: =Assumptions!G14/Assumptions!G16 | H22: The mix shift that drives the margin story.
A23: Incremental EBIT margin (change in EBIT / change in revenue) | C23: =(C16-B16)/(C7-B7) | D23: =(D16-C16)/(D7-C7) | E23: =(E16-D16)/(E7-D7) | F23: =(F16-E16)/(F7-E7) | G23: =(G16-F16)/(G7-F7) | H23: Operating leverage check.
A24: Revenue CAGR 2025A-2030E | C24: =(G7/B7)^(1/5)-1
A25: EBIT CAGR 2025A-2030E | C25: =(G16/B16)^(1/5)-1

Sheet FCF
A1: UNLEVERED FREE CASH FLOW BRIDGE
A2: FCFF = NOPAT + D&A - Capex - Change in NWC. This is what gets discounted at the WACC.
A4: EUR m | B4: 2025A | C4: 2026E | D4: 2027E | E4: 2028E | F4: 2029E | G4: 2030E | H4: Comment
A6: FREE CASH FLOW TO THE FIRM
A7: EBIT | B7: ='P&L'!B16 | C7: ='P&L'!C16 | D7: ='P&L'!D16 | E7: ='P&L'!E16 | F7: ='P&L'!F16 | G7: ='P&L'!G16
A8: (-) Tax on EBIT | B8: ='P&L'!B18 | C8: ='P&L'!C18 | D8: ='P&L'!D18 | E8: ='P&L'!E18 | F8: ='P&L'!F18 | G8: ='P&L'!G18
A9: (=) NOPAT | B9: ='P&L'!B19 | C9: ='P&L'!C19 | D9: ='P&L'!D19 | E9: ='P&L'!E19 | F9: ='P&L'!F19 | G9: ='P&L'!G19
A10: (+) Depreciation & amortisation | B10: ='P&L'!B15 | C10: ='P&L'!C15 | D10: ='P&L'!D15 | E10: ='P&L'!E15 | F10: ='P&L'!F15 | G10: ='P&L'!G15 | H10: Non-cash: added back.
A11: (-) Capital expenditure | B11: =Assumptions!B30 | C11: =Assumptions!C30 | D11: =Assumptions!D30 | E11: =Assumptions!E30 | F11: =Assumptions!F30 | G11: =Assumptions!G30 | H11: Total net investments, so it is consistent with D&A on intangibles.
A12: (-) Change in net working capital | B12: =Historical!F28 | C12: =Assumptions!C34 | D12: =Assumptions!D34 | E12: =Assumptions!E34 | F12: =Assumptions!F34 | G12: =Assumptions!G34 | H12: Negative change = WC released = CASH IN. Sign discipline is everything here.
A13: (=) UNLEVERED FREE CASH FLOW | B13: =B9+B10-B11-B12 | C13: =C9+C10-C11-C12 | D13: =D9+D10-D11-D12 | E13: =E9+E10-E11-E12 | F13: =F9+F10-F11-F12 | G13: =G9+G10-G11-G12
A14: FCF margin % | B14: =B13/'P&L'!B7 | C14: =C13/'P&L'!C7 | D14: =D13/'P&L'!D7 | E14: =E13/'P&L'!E7 | F14: =F13/'P&L'!F7 | G14: =G13/'P&L'!G7
A15: FCF growth % | C15: =C13/B13-1 | D15: =D13/C13-1 | E15: =E13/D13-1 | F15: =F13/E13-1 | G15: =G13/F13-1
A17: QUALITY CHECKS
A18: Capex / D&A (x) | B18: =B11/B10 | C18: =C11/C10 | D18: =D11/D10 | E18: =E11/E10 | F18: =F11/F10 | G18: =G11/G10 | H18: Below 1.0x forever = a shrinking asset base = an unsustainable terminal value.
A19: Cash conversion (FCF / EBITDA) | B19: =B13/'P&L'!B13 | C19: =C13/'P&L'!C13 | D19: =D13/'P&L'!D13 | E19: =E13/'P&L'!E13 | F19: =F13/'P&L'!F13 | G19: =G13/'P&L'!G13
A20: Working capital contribution as % of FCF | B20: =-B12/B13 | C20: =-C12/C13 | D20: =-D12/D13 | E20: =-E12/E13 | F20: =-F12/F13 | G20: =-G12/G13 | H20: If this is large and positive every year, your WC assumption is doing the work, not the business.

Sheet Assumptions
A1: OPERATING ASSUMPTIONS & SCENARIO ENGINE
A2: Orange cells = hardcoded inputs you control. Everything else is a formula. Explicit forecast: 2026E-2030E (5 years).
A4: EUR m unless stated | B4: 2025A | C4: 2026E | D4: 2027E | E4: 2028E | F4: 2029E | G4: 2030E | H4: Source / logic
A6: SCENARIO SWITCH
A7: Scenario (1 = Bear, 2 = Base, 3 = Bull) | B7: 2 | C7: =CHOOSE($B$7,"BEAR CASE","BASE CASE","BULL CASE") | H7: Change B7 and the entire model, the DCF and the sensitivity tables update.
A9: REVENUE BUILD (segmented: Power Solutions is volume x price, Service is installed-base driven)
A10: MW delivered | B10: =Historical!F38 | C10: =CHOOSE($B$7,C45,C46,C47) | D10: =CHOOSE($B$7,D45,D46,D47) | E10: =CHOOSE($B$7,E45,E46,E47) | F10: =CHOOSE($B$7,F45,F46,F47) | G10: =CHOOSE($B$7,G45,G46,G47) | H10: Driven by the scenario table below.
A11: MW growth % | C11: =C10/B10-1 | D11: =D10/C10-1 | E11: =E10/D10-1 | F11: =F10/E10-1 | G11: =G10/F10-1
A12: ASP - Power Solutions (EUR m / MW) | B12: =Historical!F39 | C12: 1.075 | D12: 1.09 | E12: 1.1 | F12: 1.11 | G12: 1.12 | H12: Price/mix: larger turbines and offshore lift ASP approx. 2-3% p.a.
A13: Power Solutions revenue | B13: =Historical!F35 | C13: =C10*C12 | D13: =D10*D12 | E13: =E10*E12 | F13: =F10*F12 | G13: =G10*G12
A14: Service revenue | B14: =Historical!F36 | C14: =B14*(1+C15) | D14: =C14*(1+D15) | E14: =D14*(1+E15) | F14: =E14*(1+F15) | G14: =F14*(1+G15)
A15: Service growth % | C15: 0.1 | D15: 0.09 | E15: 0.085 | F15: 0.08 | G15: 0.075 | H15: Underpinned by a EUR 38.7bn service backlog and 161 GW under service.
A16: TOTAL REVENUE | B16: =B13+B14 | C16: =C13+C14 | D16: =D13+D14 | E16: =E13+E14 | F16: =F13+F14 | G16: =G13+G14
A17: Revenue growth % | C17: =C16/B16-1 | D17: =D16/C16-1 | E17: =E16/D16-1 | F17: =F16/E16-1 | G17: =G16/F16-1
A18: CHECK: 2026E revenue vs company guidance EUR 20.0-22.0bn | C18: =IF(AND(C16>=20000,C16<=22000),"OK - within guidance","OUT OF GUIDANCE RANGE") | H18: The old model forecast EUR 19.8bn for 2026 - below the low end of guidance.
A20: MARGIN ASSUMPTIONS
A21: Gross margin % | B21: =Historical!F11 | C21: =CHOOSE($B$7,C48,C49,C50) | D21: =CHOOSE($B$7,D48,D49,D50) | E21: =CHOOSE($B$7,E48,E49,E50) | F21: =CHOOSE($B$7,F48,F49,F50) | G21: =CHOOSE($B$7,G48,G49,G50) | H21: Scenario-driven. Mix shift to Service is the main lever.
A22: Opex % of revenue | B22: =Historical!F12/Historical!F7 | C22: 0.023 | D22: 0.0225 | E22: 0.022 | F22: 0.0215 | G22: 0.021 | H22: Operating leverage on a broadly fixed cost base.
A23: EBITDA margin % | B23: =B21-B22 | C23: =C21-C22 | D23: =D21-D22 | E23: =E21-E22 | F23: =F21-F22 | G23: =G21-G22
A24: D&A % of revenue | B24: =Historical!F15/Historical!F7 | C24: 0.055 | D24: 0.0535 | E24: 0.0525 | F24: 0.0515 | G24: 0.0505
A25: EBIT margin % | B25: =B23-B24 | C25: =C23-C24 | D25: =D23-D24 | E25: =E23-E24 | F25: =F23-F24 | G25: =G23-G24
A26: CHECK: 2026E EBIT margin vs guidance 6.0-8.0% b.s.i. | C26: =IF(AND(C25>=0.06,C25<=0.08),"OK - within guidance","OUT OF GUIDANCE RANGE")
A28: CAPITAL, WORKING CAPITAL & TAX
A29: Capex % of revenue | B29: =Historical!F30 | C29: 0.057 | D29: 0.053 | E29: 0.051 | F29: 0.05 | G29: 0.05 | H29: 2026 calibrated to the approx. EUR 1.2bn guidance. Terminal capex must approach D&A.
A30: Total net investments (capex) | B30: =Historical!F29 | C30: =C16*C29 | D30: =D16*D29 | E30: =E16*E29 | F30: =F16*F29 | G30: =G16*G29
A31: Capex / D&A (x) | C31: =C30/(C16*C24) | D31: =D30/(D16*D24) | E31: =E30/(E16*E24) | F31: =F30/(F16*F24) | G31: =G30/(G16*G24) | H31: Must converge to approx. 1.0x by the terminal year or the terminal value is fiction.
A32: NWC % of revenue | B32: =Historical!F27 | C32: -0.16 | D32: -0.155 | E32: -0.15 | F32: -0.145 | G32: -0.14 | H32: 2025 was an exceptional -16.6%. We NORMALISE back toward -14%, a cash headwind.
A33: Net working capital (level) | B33: =B16*B32 | C33: =C16*C32 | D33: =D16*D32 | E33: =E16*E32 | F33: =F16*F32 | G33: =G16*G32
A34: Change in NWC (negative = cash inflow) | C34: =C33-B33 | D34: =D33-C33 | E34: =E33-D33 | F34: =F33-E33 | G34: =G33-F33 | H34: CORRECT method: change in the LEVEL. Never a fixed % of the revenue level.
A35: Effective tax rate % | B35: =Historical!F23 | C35: 0.25 | D35: 0.25 | E35: 0.25 | F35: 0.25 | G35: 0.25
A37: VALUATION PARAMETERS
A38: WACC | B38: =WACC!B30 | H38: Linked to the WACC build-up. Green = link.
A39: Terminal growth rate (g) | B39: 0.02 | H39: Must be <= long-run nominal GDP growth. 2.0% = ECB inflation target.
A40: Exit EV/EBITDA multiple (cross-check method) | B40: 10 | H40: Vestas currently trades at approx. 11.5x TTM EV/EBITDA.
A41: Mid-year convention (1 = yes, 0 = no) | B41: 1 | H41: Banks discount at t-0.5: cash arrives through the year, not on 31 December.
A43: SCENARIO INPUT TABLE (edit here, not above)
C44: 2026E | D44: 2027E | E44: 2028E | F44: 2029E | G44: 2030E
A45: MW delivered - BEAR | C45: 15200 | D45: 15400 | E45: 15600 | F45: 15700 | G45: 15800
A46: MW delivered - BASE | C46: 15800 | D46: 16300 | E46: 16900 | F46: 17300 | G46: 17600
A47: MW delivered - BULL | C47: 16300 | D47: 17200 | E47: 18100 | F47: 18800 | G47: 19400
...

Sheet WACC
A1: COST OF CAPITAL — WACC BUILD-UP
A2: Every input is sourced and dated. Never hardcode a WACC without showing this page.
A4: COST OF EQUITY — CAPM
A5: Risk-free rate (Rf) | B5: 0.0326 | D5: German 10Y Bund, 3.26% at 20-Aug-2026. Denmark is AAA and DKK is pegged to EUR.
A6: Equity risk premium (ERP) | B6: 0.05 | D6: Mature-market implied ERP (Damodaran). Update every 6 months.
A7: Country risk premium (CRP) | B7: 0 | D7: Denmark AAA -> zero. Add CRP for EM-exposed names.
A8: Levered (equity) beta | B8: 1.35 | D8: 5Y monthly vs MSCI Europe. REPLACE with your own regression / Bloomberg BETA.
A9: Size / idiosyncratic premium | B9: 0 | D9: Zero for a EUR 27bn large cap.
A10: Cost of equity (Ke = Rf + beta x (ERP+CRP) + size) | B10: =B5+B8*(B6+B7)+B9
A12: COST OF DEBT
A13: Risk-free rate | B13: =B5
A14: Credit spread | B14: 0.0105 | D14: Moody's Baa2 stable / BBB EUR industrial, approx. 105bps over Bund.
A15: Pre-tax cost of debt (Kd) | B15: =B13+B14
A16: Marginal tax rate | B16: 0.25 | D16: Denmark statutory 22%; group effective rate approx. 25%.
A17: After-tax cost of debt (Kd x (1-t)) | B17: =B15*(1-B16)
A19: CAPITAL STRUCTURE (MARKET VALUES)
A20: Share price (DKK) | B20: 204.5 | D20: Nasdaq Copenhagen, VWS, close 14-Aug-2026. UPDATE THIS BEFORE ANY INTERVIEW.
A21: Shares outstanding (m) | B21: 982.6 | D21: Net of treasury shares.
A22: EUR / DKK | B22: 7.46 | D22: DKK pegged to EUR within +/-2.25% under ERM II.
A23: Market capitalisation (EUR m) | B23: =B20*B21/B22
A24: Gross interest-bearing debt (EUR m) | B24: 3300 | D24: Bonds + EIB green loan + leases, approx. AR2024 level.
A25: Total capitalisation (D + E) | B25: =B23+B24
A26: E / (D+E) | B26: =B23/B25
A27: D / (D+E) | B27: =B24/B25
A29: WACC
A30: WACC = E/(D+E) x Ke + D/(D+E) x Kd x (1-t) | B30: =B26*B10+B27*B17 | D30: THIS is the discount rate used in the DCF sheet.
A32: CROSS-CHECKS
A33: Implied unlevered (asset) beta | B33: =B8/(1+(1-B16)*B24/B23) | D33: Sanity: should be below the levered beta.
A34: Net cash position (EUR m, + = net cash) | B34: =Historical!F31 | D34: Green font = link to another sheet.
